Workbook

Sheet 产品资料
A1: 序 | B1: 产品名称 | C1: 物料编码 | D1: 图纸编号 | E1: 零件名称 | F1: 零件规格 | G1: 材质 | H1: 单位 用量 | I1: 长度mm | J1: 宽度mm | K1: 厚度 mm | L1: 切割 周长 | M1: 切孔 数量 | N1: 面积㎡ | O1: 重量 kg | P1: 图纸目录 | Q1: 旋转 | R1: 备注
A2: 1 | B2: 46寸9斗 | C2: LP00001200 | D2: P000012 | E2: 4609底盖小加强板（0.8MM ) | F2: 0.8*119*1162 | G2: SPCC冷轧板 | H2: 1 | I2: 1162 | J2: 119 | K2: 0.8 | L2: 2.562 | M2: 8 | N2: 0.13692 | O2: =K2*N2*7.85 -> 0.8598576 | P2: D:\图纸\4609图纸\LP00001200 底盖小加强板（0.8MM ) 0.8×119×1162.dwg | Q2: 0
A3: 2 | B3: 46寸9斗 | C3: LP00001300 | D3: P000013 | E3: 4609底盖大加强板(0.8MM) | F3: 0.8*172*1162 | G3: SPCC冷轧板 | H3: 1 | I3: 1162 | J3: 172 | K3: 0.8 | L3: 2.668 | M3: 8 | N3: 0.19853 | O3: =K3*N3*7.85 -> 1.2467684 | P3: D:\图纸\4609图纸\LP00001300 底盖大加强板(0.8MM) 0.8×172×1162.dwg | Q3: 0
A4: 3 | B4: 46寸9斗 | C4: LP00002400 | D4: P000024 | E4: 4609竖槽（0.8MM) | F4: 0.8*69*563 | G4: SPCC冷轧板 | H4: 1 | I4: 563 | J4: 69 | K4: 0.8 | L4: 1.271 | M4: 0 | N4: 0.03705 | O4: =K4*N4*7.85 -> 0.232674 | P4: D:\图纸\4609图纸\LP00002400 竖槽（0.8MM) 0.8×69×563.dwg | Q4: 0
A5: 4 | B5: 46寸9斗 | C5: LP00031700 | D5: P000317 | E5: 4609顶盖（0.8MM) | F5: 0.8*552*1168.5 | G5: SPCC冷轧板 | H5: 1 | I5: 1168 | J5: 552 | K5: 0.8 | L5: 3.419 | M5: 19 | N5: 0.64367 | O5: =K5*N5*7.85 -> 4.0422476 | P5: D:\图纸\4609图纸\LP00031700 顶盖（0.8MM) 0.8×552×1168.5.dwg | Q5: -1
A6: 5 | B6: 46寸9斗 | C6: LP00031800 | D6: P000318 | E6: 4609底盖（0.8MM) | F6: 0.8*552.5*1211 | G6: SPCC冷轧板 | H6: 1 | I6: 1211 | J6: 553 | K6: 0.8 | L6: 3.581 | M6: 16 | N6: 0.66186 | O6: =K6*N6*7.85 -> 4.1564808 | P6: D:\图纸\4609图纸\LP00031800 底盖（0.8MM) 0.8×552.5×1211.dwg | Q6: -1
A7: 6 | B7: 46寸9斗 | C7: LP00031900 | D7: P000319 | E7: 4609左侧板(0.8MM) | F7: 0.8*534.5*789 | G7: SPCC冷轧板 | H7: 2 | I7: 789 | J7: 535 | K7: 0.8 | L7: 2.661 | M7: 4 | N7: 0.41702 | O7: =K7*N7*7.85 -> 2.6188856 | P7: D:\图纸\4609图纸\LP00031900 左侧板(0.8MM) 0.8×534.5×789.dwg | Q7: -1
A8: 7 | B8: 46寸9斗 | C8: LP00032100 | D8: P000321 | E8: 4609后盖板(0.8MM) | F8: 0.8*770.5*1168.5 | G8: SPCC冷轧板 | H8: 1 | I8: 1168 | J8: 771 | K8: 0.8 | L8: 3.878 | M8: 6 | N8: 0.9002 | O8: =K8*N8*7.85 -> 5.653256 | P8: D:\图纸\4609图纸\LP00032100 后盖板(0.8MM) 0.8×770.5×1168.5.dwg | Q8: -1
A9: 8 | B9: 46寸9斗 | C9: LP00032200 | D9: P000322 | E9: 4609左内垫板(0.8MM) | F9: 0.8*152*662 | G9: SPCC冷轧板 | H9: 2 | I9: 662 | J9: 152 | K9: 0.8 | L9: 1.776 | M9: 6 | N9: 0.0981 | O9: =K9*N9*7.85 -> 0.616068 | P9: D:\图纸\4609图纸\LP00032200 左内垫板(0.8MM) 0.8×152×662.dwg | Q9: 0
A10: 9 | B10: 46寸9斗 | C10: LP00032400 | D10: P000324 | E10: 4609后内垫板大槽(0.8MM) | F10: 0.8*145*754.5 | G10: SPCC冷轧板 | H10: 2 | I10: 754 | J10: 145 | K10: 0.8 | L10: 1.799 | M10: 6 | N10: 0.10932 | O10: =K10*N10*7.85 -> 0.6865296 | P10: D:\图纸\4609图纸\LP00032400 后内垫板大槽(0.8MM) 0.8×145×754.5.dwg | Q10: 0
A11: 10 | B11: 46寸9斗 | C11: LP00032500 | D11: P000325 | E11: 4609中隔板(0.8MM) | F11: 0.8*481.5*550 | G11: SPCC冷轧板 | H11: 1 | I11: 550 | J11: 482 | K11: 0.8 | L11: 2.063 | M11: 15 | N11: 0.26437 | O11: =K11*N11*7.85 -> 1.6602436 | P11: D:\图纸\4609图纸\LP00032500 中隔板(0.8MM) 0.8×481.5×550.dwg | Q11: -1
A12: 11 | B12: 46寸9斗 | C12: LP00032700 | D12: P000327 | E12: 4609中隔内垫板(0.8MM) | F12: 0.8*112*550 | G12: SPCC冷轧板 | H12: 1 | I12: 550 | J12: 112 | K12: 0.8 | L12: 1.325 | M12: 5 | N12: 0.06144 | O12: =K12*N12*7.85 -> 0.3858432 | P12: D:\图纸\4609图纸\LP00032700 中隔内垫板(0.8MM) 0.8×112×550.dwg | Q12: 0
A13: 12 | B13: 46寸9斗 | C13: LP00032800 | D13: P000328 | E13: 4609中隔内垫板大槽(0.8MM) | F13: 0.8*137*550 | G13: SPCC冷轧板 | H13: 1 | I13: 550 | J13: 137 | K13: 0.8 | L13: 1.374 | M13: 5 | N13: 0.07528 | O13: =K13*N13*7.85 -> 0.4727584 | P13: D:\图纸\4609图纸\LP00032800 中隔内垫板大槽(0.8MM) 0.8×137×550.dwg | Q13: 0
... A26: 25 | B26: 46寸9斗 | C26: LP00003200 | D26: P000032 | E26: 4609平衡杆(镀锌0.9) | F26: 0.9*74*658 | G26: SGCC镀锌板 | H26: 1 | I26: 658 | J26: 74 | K26: 0.9 | L26: 1.465 | M26: 3 | N26: 0.04791 | O26: =K26*N26*7.85 -> 0.33848415 | P26: D:\图纸\4609图纸\LP00003200 平衡杆(镀锌0.9) 0.9×74×658.dwg | Q26: 0
A27: 26 | B27: 46寸9斗 | C27: ST09001200 | E27: 4609传动轴座(0.9) | F27: 0.9*136*1250 | G27: SPCC冷轧板 | H27: 0.02 | I27: 1250 | J27: 136 | K27: 0.9 | L27: 2.772 | M27: 0 | N27: 0.17 | O27: =K27*N27*7.85 -> 1.20105 | P27: D:\图纸\4609图纸\ST09001200 传动轴座 0.9 0.9×136×1250.dwg | Q27: -1
A28: 27 | B28: 46寸9斗 | C28: ST08003000 | E28: 4609中抽屉后盖板 | F28: 0.8*73.5*493 | G28: SPCC冷轧板 | H28: 2 | I28: 493 | J28: 73.5 | K28: 0.8 | L28: 1.133 | M28: 0 | N28: 0.0362355 | O28: =K28*N28*7.85 -> 0.22755894 | P28: Rectangle | Q28: -1
A29: 28 | B29: 46寸9斗 | C29: ST08002400 | E29: 4609顶长抽屉后盖板 | F29: 0.8*77.5*1056 | G29: SPCC冷轧板 | I29: 1056 | J29: 77.5 | K29: 0.8 | L29: =1133.5*2/1000 -> 2.267 | M29: 0 | O29: =K29*N29*7.85 -> 0 | P29: Rectangle | Q29: -1

Sheet 订单数量
A1: 序号 | B1: 编号 | C1: 合同编号 | D1: 物料编码 | E1: 材质 | F1: 名称 | G1: 规格 | H1: 数量 | I1: 生产完成数量 | J1: 待生产数量 | K1: 交期 | L1: 码托数量 | M1: 备注
A2: 1 | B2: CPI-260609-5 | C2: 39407267 | D2: LP00031700 | E2: =_xlfn.XLOOKUP(D2,产品资料!C:C,产品资料!G:G) -> SPCC冷轧板 | F2: =_xlfn.XLOOKUP(D2,产品资料!C:C,产品资料!E:E) -> 4609顶盖（0.8MM) | G2: =_xlfn.XLOOKUP(D2,产品资料!C:C,产品资料!F:F) -> 0.8*552*1168.5 | H2: 3663 | I2: =SUMIFS(生产日报!J:J,生产日报!F:F,C:C,生产日报!G:G,D:D) -> 3668 | J2: =H:H-I:I -> -5 | K2: 46279
A3: 2 | B3: CPI-260609-5 | C3: 39407267 | D3: LP00001200 | E3: =_xlfn.XLOOKUP(D3,产品资料!C:C,产品资料!G:G) -> SPCC冷轧板 | F3: =_xlfn.XLOOKUP(D3,产品资料!C:C,产品资料!E:E) -> 4609底盖小加强板（0.8MM ) | G3: =_xlfn.XLOOKUP(D3,产品资料!C:C,产品资料!F:F) -> 0.8*119*1162 | H3: 3663 | I3: =SUMIFS(生产日报!J:J,生产日报!F:F,C:C,生产日报!G:G,D:D) -> 3666 | J3: =H:H-I:I -> -3 | K3: 46279
A4: 3 | B4: CPI-260609-5 | C4: 39407267 | D4: LP00001300 | E4: =_xlfn.XLOOKUP(D4,产品资料!C:C,产品资料!G:G) -> SPCC冷轧板 | F4: =_xlfn.XLOOKUP(D4,产品资料!C:C,产品资料!E:E) -> 4609底盖大加强板(0.8MM) | G4: =_xlfn.XLOOKUP(D4,产品资料!C:C,产品资料!F:F) -> 0.8*172*1162 | H4: 3663 | I4: =SUMIFS(生产日报!J:J,生产日报!F:F,C:C,生产日报!G:G,D:D) -> 3665 | J4: =H:H-I:I -> -2 | K4: 46279
A5: 4 | B5: CPI-260609-5 | C5: 39407267 | D5: LP00031800 | E5: =_xlfn.XLOOKUP(D5,产品资料!C:C,产品资料!G:G) -> SPCC冷轧板 | F5: =_xlfn.XLOOKUP(D5,产品资料!C:C,产品资料!E:E) -> 4609底盖（0.8MM) | G5: =_xlfn.XLOOKUP(D5,产品资料!C:C,产品资料!F:F) -> 0.8*552.5*1211 | H5: 3663 | I5: =SUMIFS(生产日报!J:J,生产日报!F:F,C:C,生产日报!G:G,D:D) -> 3666 | J5: =H:H-I:I -> -3 | K5: 46279
A6: 5 | B6: CPI-260609-5 | C6: 39407267 | D6: LP00031900 | E6: =_xlfn.XLOOKUP(D6,产品资料!C:C,产品资料!G:G) -> SPCC冷轧板 | F6: =_xlfn.XLOOKUP(D6,产品资料!C:C,产品资料!E:E) -> 4609左侧板(0.8MM) | G6: =_xlfn.XLOOKUP(D6,产品资料!C:C,产品资料!F:F) -> 0.8*534.5*789 | H6: 7326 | I6: =SUMIFS(生产日报!J:J,生产日报!F:F,C:C,生产日报!G:G,D:D) -> 7330 | J6: =H:H-I:I -> -4 | K6: 46279
A7: 6 | B7: CPI-260609-5 | C7: 39407267 | D7: LP00032100 | E7: =_xlfn.XLOOKUP(D7,产品资料!C:C,产品资料!G:G) -> SPCC冷轧板 | F7: =_xlfn.XLOOKUP(D7,产品资料!C:C,产品资料!E:E) -> 4609后盖板(0.8MM) | G7: =_xlfn.XLOOKUP(D7,产品资料!C:C,产品资料!F:F) -> 0.8*770.5*1168.5 | H7: 3663 | I7: =SUMIFS(生产日报!J:J,生产日报!F:F,C:C,生产日报!G:G,D:D) -> 3690 | J7: =H:H-I:I -> -27 | K7: 46279
A8: 7 | B8: CPI-260609-5 | C8: 39407267 | D8: LP00032400 | E8: =_xlfn.XLOOKUP(D8,产品资料!C:C,产品资料!G:G) -> SPCC冷轧板 | F8: =_xlfn.XLOOKUP(D8,产品资料!C:C,产品资料!E:E) -> 4609后内垫板大槽(0.8MM) | G8: =_xlfn.XLOOKUP(D8,产品资料!C:C,产品资料!F:F) -> 0.8*145*754.5 | H8: 7326 | I8: =SUMIFS(生产日报!J:J,生产日报!F:F,C:C,生产日报!G:G,D:D) -> 7330 | J8: =H:H-I:I -> -4 | K8: 46279
A9: 8 | B9: CPI-260609-5 | C9: 39407267 | D9: LP00032200 | E9: =_xlfn.XLOOKUP(D9,产品资料!C:C,产品资料!G:G) -> SPCC冷轧板 | F9: =_xlfn.XLOOKUP(D9,产品资料!C:C,产品资料!E:E) -> 4609左内垫板(0.8MM) | G9: =_xlfn.XLOOKUP(D9,产品资料!C:C,产品资料!F:F) -> 0.8*152*662 | H9: 7326 | I9: =SUMIFS(生产日报!J:J,生产日报!F:F,C:C,生产日报!G:G,D:D) -> 7330 | J9: =H:H-I:I -> -4 | K9: 46279
A10: 9 | B10: CPI-260609-5 | C10: 39407267 | D10: LP00032500 | E10: =_xlfn.XLOOKUP(D10,产品资料!C:C,产品资料!G:G) -> SPCC冷轧板 | F10: =_xlfn.XLOOKUP(D10,产品资料!C:C,产品资料!E:E) -> 4609中隔板(0.8MM) | G10: =_xlfn.XLOOKUP(D10,产品资料!C:C,产品资料!F:F) -> 0.8*481.5*550 | H10: 3663 | I10: =SUMIFS(生产日报!J:J,生产日报!F:F,C:C,生产日报!G:G,D:D) -> 3665 | J10: =H:H-I:I -> -2 | K10: 46279
A11: 10 | B11: CPI-260609-5 | C11: 39407267 | D11: LP00032700 | E11: =_xlfn.XLOOKUP(D11,产品资料!C:C,产品资料!G:G) -> SPCC冷轧板 | F11: =_xlfn.XLOOKUP(D11,产品资料!C:C,产品资料!E:E) -> 4609中隔内垫板(0.8MM) | G11: =_xlfn.XLOOKUP(D11,产品资料!C:C,产品资料!F:F) -> 0.8*112*550 | H11: 3663 | I11: =SUMIFS(生产日报!J:J,生产日报!F:F,C:C,生产日报!G:G,D:D) -> 3665 | J11: =H:H-I:I -> -2 | K11: 46279
A12: 11 | B12: CPI-260609-5 | C12: 39407267 | D12: LP00032800 | E12: =_xlfn.XLOOKUP(D12,产品资料!C:C,产品资料!G:G) -> SPCC冷轧板 | F12: =_xlfn.XLOOKUP(D12,产品资料!C:C,产品资料!E:E) -> 4609中隔内垫板大槽(0.8MM) | G12: =_xlfn.XLOOKUP(D12,产品资料!C:C,产品资料!F:F) -> 0.8*137*550 | H12: 3663 | I12: =SUMIFS(生产日报!J:J,生产日报!F:F,C:C,生产日报!G:G,D:D) -> 3665 | J12: =H:H-I:I -> -2 | K12: 46279
A13: 12 | B13: CPI-260609-5 | C13: 39407267 | D13: LP00033000 | E13: =_xlfn.XLOOKUP(D13,产品资料!C:C,产品资料!G:G) -> SPCC冷轧板 | F13: =_xlfn.XLOOKUP(D13,产品资料!C:C,产品资料!E:E) -> 4609后盖板长加强(0.8MM) | G13: =_xlfn.XLOOKUP(D13,产品资料!C:C,产品资料!F:F) -> 0.8*38.5*493 | H13: 3663 | I13: =SUMIFS(生产日报!J:J,生产日报!F:F,C:C,生产日报!G:G,D:D) -> 3677 | J13: =H:H-I:I -> -14 | K13: 46279
... A25: 24 | B25: CPI-260609-5 | C25: 39407267 | D25: LP00033900 | E25: =_xlfn.XLOOKUP(D25,产品资料!C:C,产品资料!G:G) -> SPCC冷轧板 | F25: =_xlfn.XLOOKUP(D25,产品资料!C:C,产品资料!E:E) -> 4609大拉手(0.8MM） | G25: =_xlfn.XLOOKUP(D25,产品资料!C:C,产品资料!F:F) -> 0.8*303*515 | H25: 7326 | I25: =SUMIFS(生产日报!J:J,生产日报!F:F,C:C,生产日报!G:G,D:D) -> 7329 | J25: =H:H-I:I -> -3 | K25: 46279

Sheet 生产日报
A4: 序 | B4: 日期 | C4: 班 | D4: 机台 编号 | E4: 计划单号 | F4: 合同编号 | G4: 物料编码 | H4: 名称 | I4: 规格 | J4: 合格 数量 | K4: 报废 数量 | L4: 成品 重量KG | M4: 切割 周长(米) | N4: 切孔 数量 | O4: 备注 | P4: 未打包数 | Q4: 单张 数量 | R4: 备注
A5: 1 | B5: 46116 | C5: 白 | D5: 3000W-2 | E5: JGRWD002-00001362 | F5: 39407267 | G5: LP00033000 | H5: =_xlfn.XLOOKUP(G5,产品资料!C:C,产品资料!E:E) -> 4609后盖板长加强(0.8MM) | I5: =_xlfn.XLOOKUP(G5,产品资料!C:C,产品资料!F:F) -> 0.8*38.5*493 | J5: =102*Q5-K5 -> 2008 | K5: 32 | L5: =_xlfn.XLOOKUP(G5,产品资料!C:C,产品资料!O:O)*J5 -> 238.96405 | M5: =IFERROR(_xlfn.XLOOKUP(G5,产品资料!C:C,产品资料!L:L)*J5,0) -> 2134.504 | N5: =IFERROR(_xlfn.XLOOKUP(G5,产品资料!C:C,产品资料!M:M)*J5,0) -> 4016 | O5: 0.8*1250*10210*102张(497/889) | P5: =IF(ISNUMBER(SEARCH("合包",R5)),SUMIFS(J:J,G:G,G:G,F:F,F:F)-SUMIFS(打包记录!J:J,打包记录!G:G,G:G,打包记录!F:F,F:F),SUMIFS(J:J,D:D,D:D,G:G,G:G,F:F,F:F)-SUMIFS(打包记录!J:J,打包记录!D:D,D:D,打包记录!G:G,G:G,打包记录!F:F,F:F)) -> 14 | Q5: 20 | R5: 合包
A6: 2 | B6: 46116 | C6: 夜 | D6: 3000W-2 | E6: JGRWD002-00001362 | F6: 39407267 | G6: LP00033000 | H6: =_xlfn.XLOOKUP(G6,产品资料!C:C,产品资料!E:E) -> 4609后盖板长加强(0.8MM) | I6: =_xlfn.XLOOKUP(G6,产品资料!C:C,产品资料!F:F) -> 0.8*38.5*493 | J6: 1669 | L6: =_xlfn.XLOOKUP(G6,产品资料!C:C,产品资料!O:O)*J6 -> 198.62101 | M6: =IFERROR(_xlfn.XLOOKUP(G6,产品资料!C:C,产品资料!L:L)*J6,0) -> 1774.147 | N6: =IFERROR(_xlfn.XLOOKUP(G6,产品资料!C:C,产品资料!M:M)*J6,0) -> 3338 | O6: 0.8*1250*10210*97张(594/889) 卷尾有折痕，报废数量多
A7: 3 | B7: 46189 | C7: 乙白 | D7: 3000W-2 | E7: JGRWD002-00001744 | F7: 39407267 | G7: LP00002600 | H7: =_xlfn.XLOOKUP(G7,产品资料!C:C,产品资料!E:E) -> 4609后排锁座(0.5) | I7: =_xlfn.XLOOKUP(G7,产品资料!C:C,产品资料!F:F) -> 0.5*110*755 | J7: =48*Q7-K7 -> 6256 | K7: 80 | L7: =_xlfn.XLOOKUP(G7,产品资料!C:C,产品资料!O:O)*J7 -> 2012.2659 | M7: =IFERROR(_xlfn.XLOOKUP(G7,产品资料!C:C,产品资料!L:L)*J7,0) -> 11573.6 | N7: =IFERROR(_xlfn.XLOOKUP(G7,产品资料!C:C,产品资料!M:M)*J7,0) -> 0 | O7: 0.5*1250*9125*48张 | P7: =IF(ISNUMBER(SEARCH("合包",R7)),SUMIFS(J:J,G:G,G:G,F:F,F:F)-SUMIFS(打包记录!J:J,打包记录!G:G,G:G,打包记录!F:F,F:F),SUMIFS(J:J,D:D,D:D,G:G,G:G,F:F,F:F)-SUMIFS(打包记录!J:J,打包记录!D:D,D:D,打包记录!G:G,G:G,打包记录!F:F,F:F)) -> 0 | Q7: 132
A8: 4 | B8: 46204 | C8: 乙夜 | D8: 3000W-1 | E8: JGRWD002-00001872 | F8: 39407267 | G8: LP00002400 | H8: =_xlfn.XLOOKUP(G8,产品资料!C:C,产品资料!E:E) -> 4609竖槽（0.8MM) | I8: =_xlfn.XLOOKUP(G8,产品资料!C:C,产品资料!F:F) -> 0.8*69*563 | J8: =139*Q8-K8-1130 -> 260 | L8: =_xlfn.XLOOKUP(G8,产品资料!C:C,产品资料!O:O)*J8 -> 60.49524 | M8: =IFERROR(_xlfn.XLOOKUP(G8,产品资料!C:C,产品资料!L:L)*J8,0) -> 330.46 | N8: =IFERROR(_xlfn.XLOOKUP(G8,产品资料!C:C,产品资料!M:M)*J8,0) -> 0 | P8: =IF(ISNUMBER(SEARCH("合包",R8)),SUMIFS(J:J,G:G,G:G,F:F,F:F)-SUMIFS(打包记录!J:J,打包记录!G:G,G:G,打包记录!F:F,F:F),SUMIFS(J:J,D:D,D:D,G:G,G:G,F:F,F:F)-SUMIFS(打包记录!J:J,打包记录!D:D,D:D,打包记录!G:G,G:G,打包记录!F:F,F:F)) -> 8 | Q8: 10
A9: 5 | B9: 46205 | C9: 甲白 | D9: 3000W-1 | E9: JGRWD002-00001882 | F9: 39407267 | G9: LP00002400 | H9: =_xlfn.XLOOKUP(G9,产品资料!C:C,产品资料!E:E) -> 4609竖槽（0.8MM) | I9: =_xlfn.XLOOKUP(G9,产品资料!C:C,产品资料!F:F) -> 0.8*69*563 | J9: =160*Q9-K9 -> 1578 | K9: 22 | L9: =_xlfn.XLOOKUP(G9,产品资料!C:C,产品资料!O:O)*J9 -> 367.15957 | M9: =IFERROR(_xlfn.XLOOKUP(G9,产品资料!C:C,产品资料!L:L)*J9,0) -> 2005.638 | N9: =IFERROR(_xlfn.XLOOKUP(G9,产品资料!C:C,产品资料!M:M)*J9,0) -> 0 | O9: 0.8*1250*5910*160张(600/778) | P9: =IF(ISNUMBER(SEARCH("合包",R9)),SUMIFS(J:J,G:G,G:G,F:F,F:F)-SUMIFS(打包记录!J:J,打包记录!G:G,G:G,打包记录!F:F,F:F),SUMIFS(J:J,D:D,D:D,G:G,G:G,F:F,F:F)-SUMIFS(打包记录!J:J,打包记录!D:D,D:D,打包记录!G:G,G:G,打包记录!F:F,F:F)) -> 8 | Q9: 10
A10: 6 | B10: 46205 | C10: 乙夜 | D10: 3000W-1 | E10: JGRWD002-00001882 | F10: 39407267 | G10: LP00002400 | H10: =_xlfn.XLOOKUP(G10,产品资料!C:C,产品资料!E:E) -> 4609竖槽（0.8MM) | I10: =_xlfn.XLOOKUP(G10,产品资料!C:C,产品资料!F:F) -> 0.8*69*563 | J10: =145*Q10-K10 -> 1443 | K10: 7 | L10: =_xlfn.XLOOKUP(G10,产品资料!C:C,产品资料!O:O)*J10 -> 335.74858 | M10: =IFERROR(_xlfn.XLOOKUP(G10,产品资料!C:C,产品资料!L:L)*J10,0) -> 1834.053 | N10: =IFERROR(_xlfn.XLOOKUP(G10,产品资料!C:C,产品资料!M:M)*J10,0) -> 0 | O10: 0.8*1250*5910*145张(745/778) | P10: =IF(ISNUMBER(SEARCH("合包",R10)),SUMIFS(J:J,G:G,G:G,F:F,F:F)-SUMIFS(打包记录!J:J,打包记录!G:G,G:G,打包记录!F:F,F:F),SUMIFS(J:J,D:D,D:D,G:G,G:G,F:F,F:F)-SUMIFS(打包记录!J:J,打包记录!D:D,D:D,打包记录!G:G,G:G,打包记录!F:F,F:F)) -> 8 | Q10: 10
A11: 7 | B11: 46206 | C11: 甲白 | D11: 3000W-1 | E11: JGRWD002-00001897 | F11: 39407267 | G11: LP00002400 | H11: =_xlfn.XLOOKUP(G11,产品资料!C:C,产品资料!E:E) -> 4609竖槽（0.8MM) | I11: =_xlfn.XLOOKUP(G11,产品资料!C:C,产品资料!F:F) -> 0.8*69*563 | J11: =39*Q11-K11 -> 390 | L11: =_xlfn.XLOOKUP(G11,产品资料!C:C,产品资料!O:O)*J11 -> 90.74286 | M11: =IFERROR(_xlfn.XLOOKUP(G11,产品资料!C:C,产品资料!L:L)*J11,0) -> 495.69 | N11: =IFERROR(_xlfn.XLOOKUP(G11,产品资料!C:C,产品资料!M:M)*J11,0) -> 0 | O11: 0.8*1250*5910*39张(745/778) | P11: =IF(ISNUMBER(SEARCH("合包",R11)),SUMIFS(J:J,G:G,G:G,F:F,F:F)-SUMIFS(打包记录!J:J,打包记录!G:G,G:G,打包记录!F:F,F:F),SUMIFS(J:J,D:D,D:D,G:G,G:G,F:F,F:F)-SUMIFS(打包记录!J:J,打包记录!D:D,D:D,打包记录!G:G,G:G,打包记录!F:F,F:F)) -> 8 | Q11: 10
A12: 8 | B12: 46221 | C12: 乙白 | D12: 3000W-2 | E12: JGRWD002-00001964 | F12: 39407267 | G12: LP00003200 | H12: =_xlfn.XLOOKUP(G12,产品资料!C:C,产品资料!E:E) -> 4609平衡杆(镀锌0.9) | I12: =_xlfn.XLOOKUP(G12,产品资料!C:C,产品资料!F:F) -> 0.9*74*658 | J12: =14.5*Q12-K12-32 -> 3673 | K12: 7 | L12: =_xlfn.XLOOKUP(G12,产品资料!C:C,产品资料!O:O)*J12 -> 1243.2523 | M12: =IFERROR(_xlfn.XLOOKUP(G12,产品资料!C:C,产品资料!L:L)*J12,0) -> 5380.945 | N12: =IFERROR(_xlfn.XLOOKUP(G12,产品资料!C:C,产品资料!M:M)*J12,0) -> 11019 | P12: =IF(ISNUMBER(SEARCH("合包",R12)),SUMIFS(J:J,G:G,G:G,F:F,F:F)-SUMIFS(打包记录!J:J,打包记录!G:G,G:G,打包记录!F:F,F:F),SUMIFS(J:J,D:D,D:D,G:G,G:G,F:F,F:F)-SUMIFS(打包记录!J:J,打包记录!D:D,D:D,打包记录!G:G,G:G,打包记录!F:F,F:F)) -> 10 | Q12: 256
A13: 9 | B13: 46234 | C13: 乙夜 | D13: 3000W-1 | E13: JGRWD002-00001992 | F13: 39407267 | G13: LP00031700 | H13: =_xlfn.XLOOKUP(G13,产品资料!C:C,产品资料!E:E) -> 4609顶盖（0.8MM) | I13: =_xlfn.XLOOKUP(G13,产品资料!C:C,产品资料!F:F) -> 0.8*552*1168.5 | J13: =25*Q13-K13 -> 246 | K13: 4 | L13: =_xlfn.XLOOKUP(G13,产品资料!C:C,产品资料!O:O)*J13 -> 994.39291 | M13: =IFERROR(_xlfn.XLOOKUP(G13,产品资料!C:C,产品资料!L:L)*J13,0) -> 841.074 | N13: =IFERROR(_xlfn.XLOOKUP(G13,产品资料!C:C,产品资料!M:M)*J13,0) -> 4674 | O13: 0.8*1250*5860*25张 | P13: =IF(ISNUMBER(SEARCH("合包",R13)),SUMIFS(J:J,G:G,G:G,F:F,F:F)-SUMIFS(打包记录!J:J,打包记录!G:G,G:G,打包记录!F:F,F:F),SUMIFS(J:J,D:D,D:D,G:G,G:G,F:F,F:F)-SUMIFS(打包记录!J:J,打包记录!D:D,D:D,打包记录!G:G,G:G,打包记录!F:F,F:F)) -> 0 | Q13: 10
A14: 10 | B14: 46234 | C14: 乙夜 | D14: 3000W-1 | E14: JGRWD002-00001992 | F14: 39407267 | G14: LP00001200 | H14: =_xlfn.XLOOKUP(G14,产品资料!C:C,产品资料!E:E) -> 4609底盖小加强板（0.8MM ) | I14: =_xlfn.XLOOKUP(G14,产品资料!C:C,产品资料!F:F) -> 0.8*119*1162 | J14: =25*Q14-K14 -> 121 | K14: 4 | L14: =_xlfn.XLOOKUP(G14,产品资料!C:C,产品资料!O:O)*J14 -> 104.04277 | M14: =IFERROR(_xlfn.XLOOKUP(G14,产品资料!C:C,产品资料!L:L)*J14,0) -> 310.002 | N14: =IFERROR(_xlfn.XLOOKUP(G14,产品资料!C:C,产品资料!M:M)*J14,0) -> 968 | P14: =IF(ISNUMBER(SEARCH("合包",R14)),SUMIFS(J:J,G:G,G:G,F:F,F:F)-SUMIFS(打包记录!J:J,打包记录!G:G,G:G,打包记录!F:F,F:F),SUMIFS(J:J,D:D,D:D,G:G,G:G,F:F,F:F)-SUMIFS(打包记录!J:J,打包记录!D:D,D:D,打包记录!G:G,G:G,打包记录!F:F,F:F)) -> 571 | Q14: 5
A15: 11 | B15: 46235 | C15: 乙夜 | D15: 3000W-1 | E15: JGRWD002-00001992 | F15: 39407267 | G15: LP00031700 | H15: =_xlfn.XLOOKUP(G15,产品资料!C:C,产品资料!E:E) -> 4609顶盖（0.8MM) | I15: =_xlfn.XLOOKUP(G15,产品资料!C:C,产品资料!F:F) -> 0.8*552*1168.5 | J15: =75*Q15-K15 -> 749 | K15: 1 | L15: =_xlfn.XLOOKUP(G15,产品资料!C:C,产品资料!O:O)*J15 -> 3027.6435 | M15: =IFERROR(_xlfn.XLOOKUP(G15,产品资料!C:C,产品资料!L:L)*J15,0) -> 2560.831 | N15: =IFERROR(_xlfn.XLOOKUP(G15,产品资料!C:C,产品资料!M:M)*J15,0) -> 14231 | O15: 0.8*1250*5860*75张（100/366） | P15: =IF(ISNUMBER(SEARCH("合包",R15)),SUMIFS(J:J,G:G,G:G,F:F,F:F)-SUMIFS(打包记录!J:J,打包记录!G:G,G:G,打包记录!F:F,F:F),SUMIFS(J:J,D:D,D:D,G:G,G:G,F:F,F:F)-SUMIFS(打包记录!J:J,打包记录!D:D,D:D,打包记录!G:G,G:G,打包记录!F:F,F:F)) -> 0 | Q15: 10
A16: 12 | B16: 46235 | C16: 乙夜 | D16: 3000W-1 | E16: JGRWD002-00001992 | F16: 39407267 | G16: LP00001200 | H16: =_xlfn.XLOOKUP(G16,产品资料!C:C,产品资料!E:E) -> 4609底盖小加强板（0.8MM ) | I16: =_xlfn.XLOOKUP(G16,产品资料!C:C,产品资料!F:F) -> 0.8*119*1162 | J16: =75*Q16-K16 -> 375 | L16: =_xlfn.XLOOKUP(G16,产品资料!C:C,产品资料!O:O)*J16 -> 322.4466 | M16: =IFERROR(_xlfn.XLOOKUP(G16,产品资料!C:C,产品资料!L:L)*J16,0) -> 960.75 | N16: =IFERROR(_xlfn.XLOOKUP(G16,产品资料!C:C,产品资料!M:M)*J16,0) -> 3000 | P16: =IF(ISNUMBER(SEARCH("合包",R16)),SUMIFS(J:J,G:G,G:G,F:F,F:F)-SUMIFS(打包记录!J:J,打包记录!G:G,G:G,打包记录!F:F,F:F),SUMIFS(J:J,D:D,D:D,G:G,G:G,F:F,F:F)-SUMIFS(打包记录!J:J,打包记录!D:D,D:D,打包记录!G:G,G:G,打包记录!F:F,F:F)) -> 571 | Q16: 5
A17: 13 | B17: 46237 | C17: 乙白 | D17: 3000W-2 | E17: JGRWD002-00001992 | F17: 39407267 | G17: LP00031900 | H17: =_xlfn.XLOOKUP(G17,产品资料!C:C,产品资料!E:E) -> 4609左侧板(0.8MM) | I17: =_xlfn.XLOOKUP(G17,产品资料!C:C,产品资料!F:F) -> 0.8*534.5*789 | J17: =65*Q17-K17 -> 1816 | K17: 4 | L17: =_xlfn.XLOOKUP(G17,产品资料!C:C,产品资料!O:O)*J17 -> 4755.8962 | M17: =IFERROR(_xlfn.XLOOKUP(G17,产品资料!C:C,产品资料!L:L)*J17,0) -> 4832.376 | N17: =IFERROR(_xlfn.XLOOKUP(G17,产品资料!C:C,产品资料!M:M)*J17,0) -> 7264 | O17: 0.8*1250*11660*65张 | P17: =IF(ISNUMBER(SEARCH("合包",R17)),SUMIFS(J:J,G:G,G:G,F:F,F:F)-SUMIFS(打包记录!J:J,打包记录!G:G,G:G,打包记录!F:F,F:F),SUMIFS(J:J,D:D,D:D,G:G,G:G,F:F,F:F)-SUMIFS(打包记录!J:J,打包记录!D:D,D:D,打包记录!G:G,G:G,打包记录!F:F,F:F)) -> 4 | Q17: 28
A18: 14 | B18: 46237 | C18: 乙白 | D18: 3000W-2 | E18: JGRWD002-00001992 | F18: 39407267 | G18: LP00032400 | H18: =_xlfn.XLOOKUP(G18,产品资料!C:C,产品资料!E:E) -> 4609后内垫板大槽(0.8MM) | I18: =_xlfn.XLOOKUP(G18,产品资料!C:C,产品资料!F:F) -> 0.8*145*754.5 | J18: =65*Q18-K18 -> 260 | L18: =_xlfn.XLOOKUP(G18,产品资料!C:C,产品资料!O:O)*J18 -> 178.4977 | M18: =IFERROR(_xlfn.XLOOKUP(G18,产品资料!C:C,产品资料!L:L)*J18,0) -> 467.74 | N18: =IFERROR(_xlfn.XLOOKUP(G18,产品资料!C:C,产品资料!M:M)*J18,0) -> 1560 | P18: =IF(ISNUMBER(SEARCH("合包",R18)),SUMIFS(J:J,G:G,G:G,F:F,F:F)-SUMIFS(打包记录!J:J,打包记录!G:G,G:G,打包记录!F:F,F:F),SUMIFS(J:J,D:D,D:D,G:G,G:G,F:F,F:F)-SUMIFS(打包记录!J:J,打包记录!D:D,D:D,打包记录!G:G,G:G,打包记录!F:F,F:F)) -> 4 | Q18: 4
A19: 15 | B19: 46237 | C19: 乙白 | D19: 3000W-2 | E19: JGRWD002-00001992 | F19: 39407267 | G19: LP00033300 | H19: =_xlfn.XLOOKUP(G19,产品资料!C:C,产品资料!E:E) -> 4609顶长拉手（0.8MM ） | I19: =_xlfn.XLOOKUP(G19,产品资料!C:C,产品资料!F:F) -> 0.8*168*1076 | J19: =65*Q19-K19 -> 520 | L19: =_xlfn.XLOOKUP(G19,产品资料!C:C,产品资料!O:O)*J19 -> 588.36315 | M19: =IFERROR(_xlfn.XLOOKUP(G19,产品资料!C:C,产品资料!L:L)*J19,0) -> 1290.64 | N19: =IFERROR(_xlfn.XLOOKUP(G19,产品资料!C:C,产品资料!M:M)*J19,0) -> 0 | P19: =IF(ISNUMBER(SEARCH("合包",R19)),SUMIFS(J:J,G:G,G:G,F:F,F:F)-SUMIFS(打包记录!J:J,打包记录!G:G,G:G,打包记录!F:F,F:F),SUMIFS(J:J,D:D,D:D,G:G,G:G,F:F,F:F)-SUMIFS(打包记录!J:J,打包记录!D:D,D:D,打包记录!G:G,G:G,打包记录!F:F,F:F)) -> 2 | Q19: 8
A20: 16 | B20: 46237 | C20: 乙白 | D20: 3000W-2 | E20: JGRWD002-00001992 | F20: 39407267 | G20: LP00033900 | H20: =_xlfn.XLOOKUP(G20,产品资料!C:C,产品资料!E:E) -> 4609大拉手(0.8MM） | I20: =_xlfn.XLOOKUP(G20,产品资料!C:C,产品资料!F:F) -> 0.8*303*515 | J20: =65*Q20-K20 -> 260 | L20: =_xlfn.XLOOKUP(G20,产品资料!C:C,产品资料!O:O)*J20 -> 254.22696 | M20: =IFERROR(_xlfn.XLOOKUP(G20,产品资料!C:C,产品资料!L:L)*J20,0) -> 423.8 | N20: =IFERROR(_xlfn.XLOOKUP(G20,产品资料!C:C,产品资料!M:M)*J20,0) -> 0 | P20: =IF(ISNUMBER(SEARCH("合包",R20)),SUMIFS(J:J,G:G,G:G,F:F,F:F)-SUMIFS(打包记录!J:J,打包记录!G:G,G:G,打包记录!F:F,F:F),SUMIFS(J:J,D:D,D:D,G:G,G:G,F:F,F:F)-SUMIFS(打包记录!J:J,打包记录!D:D,D:D,打包记录!G:G,G:G,打包记录!F:F,F:F)) -> 3 | Q20: 4
A21: 17 | B21: 46238 | C21: 乙白 | D21: 3000W-2 | E21: JGRWD002-00002047 | F21: 39407267 | G21: LP00031900 | H21: =_xlfn.XLOOKUP(G21,产品资料!C:C,产品资料!E:E) -> 4609左侧板(0.8MM) | I21: =_xlfn.XLOOKUP(G21,产品资料!C:C,产品资料!F:F) -> 0.8*534.5*789 | J21: =108*Q21-K21 -> 3015 | K21: 9 | L21: =_xlfn.XLOOKUP(G21,产品资料!C:C,产品资料!O:O)*J21 -> 7895.9401 | M21: =IFERROR(_xlfn.XLOOKUP(G21,产品资料!C:C,产品资料!L:L)*J21,0) -> 8022.915 | N21: =IFERROR(_xlfn.XLOOKUP(G21,产品资料!C:C,产品资料!M:M)*J21,0) -> 12060 | O21: 0.8*1250*11660*108张（173/262） | P21: =IF(ISNUMBER(SEARCH("合包",R21)),SUMIFS(J:J,G:G,G:G,F:F,F:F)-SUMIFS(打包记录!J:J,打包记录!G:G,G:G,打包记录!F:F,F:F),SUMIFS(J:J,D:D,D:D,G:G,G:G,F:F,F:F)-SUMIFS(打包记录!J:J,打包记录!D:D,D:D,打包记录!G:G,G:G,打包记录!F:F,F:F)) -> 4 | Q21: 28
A22: 18 | B22: 46238 | C22: 乙白 | D22: 3000W-2 | E22: JGRWD002-00002047 | F22: 39407267 | G22: LP00032400 | H22: =_xlfn.XLOOKUP(G22,产品资料!C:C,产品资料!E:E) -> 4609后内垫板大槽(0.8MM) | I22: =_xlfn.XLOOKUP(G22,产品资料!C:C,产品资料!F:F) -> 0.8*145*754.5 | J22: =108*Q22-K22 -> 425 | K22: 7 | L22: =_xlfn.XLOOKUP(G22,产品资料!C:C,产品资料!O:O)*J22 -> 291.77508 | M22: =IFERROR(_xlfn.XLOOKUP(G22,产品资料!C:C,产品资料!L:L)*J22,0) -> 764.575 | N22: =IFERROR(_xlfn.XLOOKUP(G22,产品资料!C:C,产品资料!M:M)*J22,0) -> 2550 | P22: =IF(ISNUMBER(SEARCH("合包",R22)),SUMIFS(J:J,G:G,G:G,F:F,F:F)-SUMIFS(打包记录!J:J,打包记录!G:G,G:G,打包记录!F:F,F:F),SUMIFS(J:J,D:D,D:D,G:G,G:G,F:F,F:F)-SUMIFS(打包记录!J:J,打包记录!D:D,D:D,打包记录!G:G,G:G,打包记录!F:F,F:F)) -> 4 | Q22: 4
A23: 19 | B23: 46238 | C23: 乙白 | D23: 3000W-2 | E23: JGRWD002-00002047 | F23: 39407267 | G23: LP00033300 | H23: =_xlfn.XLOOKUP(G23,产品资料!C:C,产品资料!E:E) -> 4609顶长拉手（0.8MM ） | I23: =_xlfn.XLOOKUP(G23,产品资料!C:C,产品资料!F:F) -> 0.8*168*1076 | J23: =108*Q23-K23 -> 849 | K23: 15 | L23: =_xlfn.XLOOKUP(G23,产品资料!C:C,产品资料!O:O)*J23 -> 960.61599 | M23: =IFERROR(_xlfn.XLOOKUP(G23,产品资料!C:C,产品资料!L:L)*J23,0) -> 2107.218 | N23: =IFERROR(_xlfn.XLOOKUP(G23,产品资料!C:C,产品资料!M:M)*J23,0) -> 0 | P23: =IF(ISNUMBER(SEARCH("合包",R23)),SUMIFS(J:J,G:G,G:G,F:F,F:F)-SUMIFS(打包记录!J:J,打包记录!G:G,G:G,打包记录!F:F,F:F),SUMIFS(J:J,D:D,D:D,G:G,G:G,F:F,F:F)-SUMIFS(打包记录!J:J,打包记录!D:D,D:D,打包记录!G:G,G:G,打包记录!F:F,F:F)) -> 2 | Q23: 8
A24: 20 | B24: 46238 | C24: 乙白 | D24: 3000W-2 | E24: JGRWD002-00002047 | F24: 39407267 | G24: LP00033900 | H24: =_xlfn.XLOOKUP(G24,产品资料!C:C,产品资料!E:E) -> 4609大拉手(0.8MM） | I24: =_xlfn.XLOOKUP(G24,产品资料!C:C,产品资料!F:F) -> 0.8*303*515 | J24: =108*Q24-K24 -> 426 | K24: 6 | L24: =_xlfn.XLOOKUP(G24,产品资料!C:C,产品资料!O:O)*J24 -> 416.5411 | M24: =IFERROR(_xlfn.XLOOKUP(G24,产品资料!C:C,产品资料!L:L)*J24,0) -> 694.38 | N24: =IFERROR(_xlfn.XLOOKUP(G24,产品资料!C:C,产品资料!M:M)*J24,0) -> 0 | P24: =IF(ISNUMBER(SEARCH("合包",R24)),SUMIFS(J:J,G:G,G:G,F:F,F:F)-SUMIFS(打包记录!J:J,打包记录!G:G,G:G,打包记录!F:F,F:F),SUMIFS(J:J,D:D,D:D,G:G,G:G,F:F,F:F)-SUMIFS(打包记录!J:J,打包记录!D:D,D:D,打包记录!G:G,G:G,打包记录!F:F,F:F)) -> 3 | Q24: 4
A25: 21 | B25: 46239 | C25: 乙白 | D25: 3000W-2 | E25: JGRWD002-00002047 | F25: 39407267 | G25: LP00031900 | H25: =_xlfn.XLOOKUP(G25,产品资料!C:C,产品资料!E:E) -> 4609左侧板(0.8MM) | I25: =_xlfn.XLOOKUP(G25,产品资料!C:C,产品资料!F:F) -> 0.8*534.5*789 | J25: =90*Q25-K25 -> 2499 | K25: 21 | L25: =_xlfn.XLOOKUP(G25,产品资料!C:C,产品资料!O:O)*J25 -> 6544.5951 | M25: =IFERROR(_xlfn.XLOOKUP(G25,产品资料!C:C,产品资料!L:L)*J25,0) -> 6649.839 | N25: =IFERROR(_xlfn.XLOOKUP(G25,产品资料!C:C,产品资料!M:M)*J25,0) -> 9996 | O25: 0.8*1250*11660*90张（263/263） | P25: =IF(ISNUMBER(SEARCH("合包",R25)),SUMIFS(J:J,G:G,G:G,F:F,F:F)-SUMIFS(打包记录!J:J,打包记录!G:G,G:G,打包记录!F:F,F:F),SUMIFS(J:J,D:D,D:D,G:G,G:G,F:F,F:F)-SUMIFS(打包记录!J:J,打包记录!D:D,D:D,打包记录!G:G,G:G,打包记录!F:F,F:F)) -> 4 | Q25: 28
A26: 22 | B26: 46239 | C26: 乙白 | D26: 3000W-2 | E26: JGRWD002-00002047 | F26: 39407267 | G26: LP00032400 | H26: =_xlfn.XLOOKUP(G26,产品资料!C:C,产品资料!E:E) -> 4609后内垫板大槽(0.8MM) | I26: =_xlfn.XLOOKUP(G26,产品资料!C:C,产品资料!F:F) -> 0.8*145*754.5 | J26: =90*Q26-K26 -> 348 | K26: 12 | L26: =_xlfn.XLOOKUP(G26,产品资料!C:C,产品资料!O:O)*J26 -> 238.9123 | M26: =IFERROR(_xlfn.XLOOKUP(G26,产品资料!C:C,产品资料!L:L)*J26,0) -> 626.052 | N26: =IFERROR(_xlfn.XLOOKUP(G26,产品资料!C:C,产品资料!M:M)*J26,0) -> 2088 | P26: =IF(ISNUMBER(SEARCH("合包",R26)),SUMIFS(J:J,G:G,G:G,F:F,F:F)-SUMIFS(打包记录!J:J,打包记录!G:G,G:G,打包记录!F:F,F:F),SUMIFS(J:J,D:D,D:D,G:G,G:G,F:F,F:F)-SUMIFS(打包记录!J:J,打包记录!D:D,D:D,打包记录!G:G,G:G,打包记录!F:F,F:F)) -> 4 | Q26: 4
A27: 23 | B27: 46239 | C27: 乙白 | D27: 3000W-2 | E27: JGRWD002-00002047 | F27: 39407267 | G27: LP00033300 | H27: =_xlfn.XLOOKUP(G27,产品资料!C:C,产品资料!E:E) -> 4609顶长拉手（0.8MM ） | I27: =_xlfn.XLOOKUP(G27,产品资料!C:C,产品资料!F:F) -> 0.8*168*1076 | J27: =90*Q27-K27 -> 690 | K27: 30 | L27: =_xlfn.XLOOKUP(G27,产品资料!C:C,产品资料!O:O)*J27 -> 780.71264 | M27: =IFERROR(_xlfn.XLOOKUP(G27,产品资料!C:C,产品资料!L:L)*J27,0) -> 1712.58 | N27: =IFERROR(_xlfn.XLOOKUP(G27,产品资料!C:C,产品资料!M:M)*J27,0) -> 0 | P27: =IF(ISNUMBER(SEARCH("合包",R27)),SUMIFS(J:J,G:G,G:G,F:F,F:F)-SUMIFS(打包记录!J:J,打包记录!G:G,G:G,打包记录!F:F,F:F),SUMIFS(J:J,D:D,D:D,G:G,G:G,F:F,F:F)-SUMIFS(打包记录!J:J,打包记录!D:D,D:D,打包记录!G:G,G:G,打包记录!F:F,F:F)) -> 2 | Q27: 8
A28: 24 | B28: 46239 | C28: 乙白 | D28: 3000W-2 | E28: JGRWD002-00002047 | F28: 39407267 | G28: LP00033900 | H28: =_xlfn.XLOOKUP(G28,产品资料!C:C,产品资料!E:E) -> 4609大拉手(0.8MM） | I28: =_xlfn.XLOOKUP(G28,产品资料!C:C,产品资料!F:F) -> 0.8*303*515 | J28: =90*Q28-K28 -> 359 | K28: 1 | L28: =_xlfn.XLOOKUP(G28,产品资料!C:C,产品资料!O:O)*J28 -> 351.02876 | M28: =IFERROR(_xlfn.XLOOKUP(G28,产品资料!C:C,产品资料!L:L)*J28,0) -> 585.17 | N28: =IFERROR(_xlfn.XLOOKUP(G28,产品资料!C:C,产品资料!M:M)*J28,0) -> 0 | P28: =IF(ISNUMBER(SEARCH("合包",R28)),SUMIFS(J:J,G:G,G:G,F:F,F:F)-SUMIFS(打包记录!J:J,打包记录!G:G,G:G,打包记录!F:F,F:F),SUMIFS(J:J,D:D,D:D,G:G,G:G,F:F,F:F)-SUMIFS(打包记录!J:J,打包记录!D:D,D:D,打包记录!G:G,G:G,打包记录!F:F,F:F)) -> 3 | Q28: 4
A29: 25 | B29: 46239 | C29: 乙白 | D29: 3000W-2 | E29: JGRWD002-00002047 | F29: 39407267 | G29: LP00032200 | H29: =_xlfn.XLOOKUP(G29,产品资料!C:C,产品资料!E:E) -> 4609左内垫板(0.8MM) | I29: =_xlfn.XLOOKUP(G29,产品资料!C:C,产品资料!F:F) -> 0.8*152*662 | J29: =11*Q29-K29 -> 176 | L29: =_xlfn.XLOOKUP(G29,产品资料!C:C,产品资料!O:O)*J29 -> 108.42797 | M29: =IFERROR(_xlfn.XLOOKUP(G29,产品资料!C:C,产品资料!L:L)*J29,0) -> 312.576 | N29: =IFERROR(_xlfn.XLOOKUP(G29,产品资料!C:C,产品资料!M:M)*J29,0) -> 1056 | O29: 0.8*1250*11790*11张（11/191） | P29: =IF(ISNUMBER(SEARCH("合包",R29)),SUMIFS(J:J,G:G,G:G,F:F,F:F)-SUMIFS(打包记录!J:J,打包记录!G:G,G:G,打包记录!F:F,F:F),SUMIFS(J:J,D:D,D:D,G:G,G:G,F:F,F:F)-SUMIFS(打包记录!J:J,打包记录!D:D,D:D,打包记录!G:G,G:G,打包记录!F:F,F:F)) -> 4 | Q29: 16
A30: 26 | B30: 46239 | C30: 乙白 | D30: 3000W-2 | E30: JGRWD002-00002047 | F30: 39407267 | G30: LP00033300 | H30: =_xlfn.XLOOKUP(G30,产品资料!C:C,产品资料!E:E) -> 4609顶长拉手（0.8MM ） | I30: =_xlfn.XLOOKUP(G30,产品资料!C:C,产品资料!F:F) -> 0.8*168*1076 | J30: =11*Q30-K30 -> 88 | L30: =_xlfn.XLOOKUP(G30,产品资料!C:C,产品资料!O:O)*J30 -> 99.569149 | M30: =IFERROR(_xlfn.XLOOKUP(G30,产品资料!C:C,产品资料!L:L)*J30,0) -> 218.416 | N30: =IFERROR(_xlfn.XLOOKUP(G30,产品资料!C:C,产品资料!M:M)*J30,0) -> 0 | P30: =IF(ISNUMBER(SEARCH("合包",R30)),SUMIFS(J:J,G:G,G:G,F:F,F:F)-SUMIFS(打包记录!J:J,打包记录!G:G,G:G,打包记录!F:F,F:F),SUMIFS(J:J,D:D,D:D,G:G,G:G,F:F,F:F)-SUMIFS(打包记录!J:J,打包记录!D:D,D:D,打包记录!G:G,G:G,打包记录!F:F,F:F)) -> 2 | Q30: 8
A31: 27 | B31: 46239 | C31: 乙白 | D31: 3000W-2 | E31: JGRWD002-00002047 | F31: 39407267 | G31: LP00033700 | H31: =_xlfn.XLOOKUP(G31,产品资料!C:C,产品资料!E:E) -> 4609中拉手(0.8MM） | I31: =_xlfn.XLOOKUP(G31,产品资料!C:C,产品资料!F:F) -> 0.8*155*515 | J31: =11*Q31-K31 -> 88 | L31: =_xlfn.XLOOKUP(G31,产品资料!C:C,产品资料!O:O)*J31 -> 43.923827 | M31: =IFERROR(_xlfn.XLOOKUP(G31,产品资料!C:C,产品资料!L:L)*J31,0) -> 117.392 | N31: =IFERROR(_xlfn.XLOOKUP(G31,产品资料!C:C,产品资料!M:M)*J31,0) -> 0 | P31: =IF(ISNUMBER(SEARCH("合包",R31)),SUMIFS(J:J,G:G,G:G,F:F,F:F)-SUMIFS(打包记录!J:J,打包记录!G:G,G:G,打包记录!F:F,F:F),SUMIFS(J:J,D:D,D:D,G:G,G:G,F:F,F:F)-SUMIFS(打包记录!J:J,打包记录!D:D,D:D,打包记录!G:G,G:G,打包记录!F:F,F:F)) -> 10 | Q31: 8
A32: 28 | B32: 46239 | C32: 乙白 | D32: 3000W-2 | E32: JGRWD002-00002047 | F32: 39407267 | G32: LP00033800 | H32: =_xlfn.XLOOKUP(G32,产品资料!C:C,产品资料!E:E) -> 4609大抽斗(0.8MM) | I32: =_xlfn.XLOOKUP(G32,产品资料!C:C,产品资料!F:F) -> 0.8*418*919 | J32: =11*Q32-K32 -> 308 | L32: =_xlfn.XLOOKUP(G32,产品资料!C:C,产品资料!O:O)*J32 -> 739.69206 | M32: =IFERROR(_xlfn.XLOOKUP(G32,产品资料!C:C,产品资料!L:L)*J32,0) -> 838.068 | N32: =IFERROR(_xlfn.XLOOKUP(G32,产品资料!C:C,产品资料!M:M)*J32,0) -> 5544 | P32: =IF(ISNUMBER(SEARCH("合包",R32)),SUMIFS(J:J,G:G,G:G,F:F,F:F)-SUMIFS(打包记录!J:J,打包记录!G:G,G:G,打包记录!F:F,F:F),SUMIFS(J:J,D:D,D:D,G:G,G:G,F:F,F:F)-SUMIFS(打包记录!J:J,打包记录!D:D,D:D,打包记录!G:G,G:G,打包记录!F:F,F:F)) -> 2 | Q32: 28
A33: 29 | B33: 46239 | C33: 甲夜 | D33: 3000W-1 | E33: JGRWD002-00002047 | F33: 39407267 | G33: LP00031700 | H33: =_xlfn.XLOOKUP(G33,产品资料!C:C,产品资料!E:E) -> 4609顶盖（0.8MM) | I33: =_xlfn.XLOOKUP(G33,产品资料!C:C,产品资料!F:F) -> 0.8*552*1168.5 | J33: =33*Q33-K33 -> 328 | K33: 2 | L33: =_xlfn.XLOOKUP(G33,产品资料!C:C,产品资料!O:O)*J33 -> 1325.8572 | M33: =IFERROR(_xlfn.XLOOKUP(G33,产品资料!C:C,产品资料!L:L)*J33,0) -> 1121.432 | N33: =IFERROR(_xlfn.XLOOKUP(G33,产品资料!C:C,产品资料!M:M)*J33,0) -> 6232 | O33: 0.8*1250*5860*33张 | P33: =IF(ISNUMBER(SEARCH("合包",R33)),SUMIFS(J:J,G:G,G:G,F:F,F:F)-SUMIFS(打包记录!J:J,打包记录!G:G,G:G,打包记录!F:F,F:F),SUMIFS(J:J,D:D,D:D,G:G,G:G,F:F,F:F)-SUMIFS(打包记录!J:J,打包记录!D:D,D:D,打包记录!G:G,G:G,打包记录!F:F,F:F)) -> 0 | Q33: 10
A34: 30 | B34: 46239 | C34: 甲夜 | D34: 3000W-1 | E34: JGRWD002-00002047 | F34: 39407267 | G34: LP00001200 | H34: =_xlfn.XLOOKUP(G34,产品资料!C:C,产品资料!E:E) -> 4609底盖小加强板（0.8MM ) | I34: =_xlfn.XLOOKUP(G34,产品资料!C:C,产品资料!F:F) -> 0.8*119*1162 | J34: =33*Q34-K34 -> 158 | K34: 7 | L34: =_xlfn.XLOOKUP(G34,产品资料!C:C,产品资料!O:O)*J34 -> 135.8575 | M34: =IFERROR(_xlfn.XLOOKUP(G34,产品资料!C:C,产品资料!L:L)*J34,0) -> 404.796 | N34: =IFERROR(_xlfn.XLOOKUP(G34,产品资料!C:C,产品资料!M:M)*J34,0) -> 1264 | P34: =IF(ISNUMBER(SEARCH("合包",R34)),SUMIFS(J:J,G:G,G:G,F:F,F:F)-SUMIFS(打包记录!J:J,打包记录!G:G,G:G,打包记录!F:F,F:F),SUMIFS(J:J,D:D,D:D,G:G,G:G,F:F,F:F)-SUMIFS(打包记录!J:J,打包记录!D:D,D:D,打包记录!G:G,G:G,打包记录!F:F,F:F)) -> 571 | Q34: 5
A35: 31 | B35: 46240 | C35: 甲夜 | D35: 3000W-1 | E35: JGRWD002-00002047 | F35: 39407267 | G35: LP00031700 | H35: =_xlfn.XLOOKUP(G35,产品资料!C:C,产品资料!E:E) -> 4609顶盖（0.8MM) | I35: =_xlfn.XLOOKUP(G35,产品资料!C:C,产品资料!F:F) -> 0.8*552*1168.5 | J35: =27*Q35-K35 -> 268 | K35: 2 | L35: =_xlfn.XLOOKUP(G35,产品资料!C:C,产品资料!O:O)*J35 -> 1083.3224 | M35: =IFERROR(_xlfn.XLOOKUP(G35,产品资料!C:C,产品资料!L:L)*J35,0) -> 916.292 | N35: =IFERROR(_xlfn.XLOOKUP(G35,产品资料!C:C,产品资料!M:M)*J35,0) -> 5092 | O35: 0.8*1250*5860*27张 | P35: =IF(ISNUMBER(SEARCH("合包",R35)),SUMIFS(J:J,G:G,G:G,F:F,F:F)-SUMIFS(打包记录!J:J,打包记录!G:G,G:G,打包记录!F:F,F:F),SUMIFS(J:J,D:D,D:D,G:G,G:G,F:F,F:F)-SUMIFS(打包记录!J:J,打包记录!D:D,D:D,打包记录!G:G,G:G,打包记录!F:F,F:F)) -> 0 | Q35: 10
A36: 32 | B36: 46240 | C36: 甲夜 | D36: 3000W-1 | E36: JGRWD002-00002047 | F36: 39407267 | G36: LP00001200 | H36: =_xlfn.XLOOKUP(G36,产品资料!C:C,产品资料!E:E) -> 4609底盖小加强板（0.8MM ) | I36: =_xlfn.XLOOKUP(G36,产品资料!C:C,产品资料!F:F) -> 0.8*119*1162 | J36: =27*Q36-K36 -> 131 | K36: 4 | L36: =_xlfn.XLOOKUP(G36,产品资料!C:C,产品资料!O:O)*J36 -> 112.64135 | M36: =IFERROR(_xlfn.XLOOKUP(G36,产品资料!C:C,产品资料!L:L)*J36,0) -> 335.622 | N36: =IFERROR(_xlfn.XLOOKUP(G36,产品资料!C:C,产品资料!M:M)*J36,0) -> 1048 | P36: =IF(ISNUMBER(SEARCH("合包",R36)),SUMIFS(J:J,G:G,G:G,F:F,F:F)-SUMIFS(打包记录!J:J,打包记录!G:G,G:G,打包记录!F:F,F:F),SUMIFS(J:J,D:D,D:D,G:G,G:G,F:F,F:F)-SUMIFS(打包记录!J:J,打包记录!D:D,D:D,打包记录!G:G,G:G,打包记录!F:F,F:F)) -> 571 | Q36: 5
A37: 33 | B37: 46240 | C37: 甲白 | D37: 3000W-2 | E37: JGRWD002-00002047 | F37: 39407267 | G37: LP00032200 | H37: =_xlfn.XLOOKUP(G37,产品资料!C:C,产品资料!E:E) -> 4609左内垫板(0.8MM) | I37: =_xlfn.XLOOKUP(G37,产品资料!C:C,产品资料!F:F) -> 0.8*152*662 | J37: =66*Q37-K37 -> 1052 | K37: 4 | L37: =_xlfn.XLOOKUP(G37,产品资料!C:C,产品资料!O:O)*J37 -> 648.10354 | M37: =IFERROR(_xlfn.XLOOKUP(G37,产品资料!C:C,产品资料!L:L)*J37,0) -> 1868.352 | N37: =IFERROR(_xlfn.XLOOKUP(G37,产品资料!C:C,产品资料!M:M)*J37,0) -> 6312 | O37: 0.8*1250*11790*66张（77/191） | P37: =IF(ISNUMBER(SEARCH("合包",R37)),SUMIFS(J:J,G:G,G:G,F:F,F:F)-SUMIFS(打包记录!J:J,打包记录!G:G,G:G,打包记录!F:F,F:F),SUMIFS(J:J,D:D,D:D,G:G,G:G,F:F,F:F)-SUMIFS(打包记录!J:J,打包记录!D:D,D:D,打包记录!G:G,G:G,打包记录!F:F,F:F)) -> 4 | Q37: 16
A38: 34 | B38: 46240 | C38: 甲白 | D38: 3000W-2 | E38: JGRWD002-00002047 | F38: 39407267 | G38: LP00033300 | H38: =_xlfn.XLOOKUP(G38,产品资料!C:C,产品资料!E:E) -> 4609顶长拉手（0.8MM ） | I38: =_xlfn.XLOOKUP(G38,产品资料!C:C,产品资料!F:F) -> 0.8*168*1076 | J38: =66*Q38-K38 -> 527 | K38: 1 | L38: =_xlfn.XLOOKUP(G38,产品资料!C:C,产品资料!O:O)*J38 -> 596.28343 | M38: =IFERROR(_xlfn.XLOOKUP(G38,产品资料!C:C,产品资料!L:L)*J38,0) -> 1308.014 | N38: =IFERROR(_xlfn.XLOOKUP(G38,产品资料!C:C,产品资料!M:M)*J38,0) -> 0 | P38: =IF(ISNUMBER(SEARCH("合包",R38)),SUMIFS(J:J,G:G,G:G,F:F,F:F)-SUMIFS(打包记录!J:J,打包记录!G:G,G:G,打包记录!F:F,F:F),SUMIFS(J:J,D:D,D:D,G:G,G:G,F:F,F:F)-SUMIFS(打包记录!J:J,打包记录!D:D,D:D,打包记录!G:G,G:G,打包记录!F:F,F:F)) -> 2 | Q38: 8
A39: 35 | B39: 46240 | C39: 甲白 | D39: 3000W-2 | E39: JGRWD002-00002047 | F39: 39407267 | G39: LP00033700 | H39: =_xlfn.XLOOKUP(G39,产品资料!C:C,产品资料!E:E) -> 4609中拉手(0.8MM） | I39: =_xlfn.XLOOKUP(G39,产品资料!C:C,产品资料!F:F) -> 0.8*155*515 | J39: =66*Q39-K39 -> 528 | L39: =_xlfn.XLOOKUP(G39,产品资料!C:C,产品资料!O:O)*J39 -> 263.54296 | M39: =IFERROR(_xlfn.XLOOKUP(G39,产品资料!C:C,产品资料!L:L)*J39,0) -> 704.352 | N39: =IFERROR(_xlfn.XLOOKUP(G39,产品资料!C:C,产品资料!M:M)*J39,0) -> 0 | P39: =IF(ISNUMBER(SEARCH("合包",R39)),SUMIFS(J:J,G:G,G:G,F:F,F:F)-SUMIFS(打包记录!J:J,打包记录!G:G,G:G,打包记录!F:F,F:F),SUMIFS(J:J,D:D,D:D,G:G,G:G,F:F,F:F)-SUMIFS(打包记录!J:J,打包记录!D:D,D:D,打包记录!G:G,G:G,打包记录!F:F,F:F)) -> 10 | Q39: 8
A40: 36 | B40: 46240 | C40: 甲白 | D40: 3000W-2 | E40: JGRWD002-00002047 | F40: 39407267 | G40: LP00033800 | H40: =_xlfn.XLOOKUP(G40,产品资料!C:C,产品资料!E:E) -> 4609大抽斗(0.8MM) | I40: =_xlfn.XLOOKUP(G40,产品资料!C:C,产品资料!F:F) -> 0.8*418*919 | J40: =66*Q40-K40 -> 1847 | K40: 1 | L40: =_xlfn.XLOOKUP(G40,产品资料!C:C,产品资料!O:O)*J40 -> 4435.7508 | M40: =IFERROR(_xlfn.XLOOKUP(G40,产品资料!C:C,产品资料!L:L)*J40,0) -> 5025.687 | N40: =IFERROR(_xlfn.XLOOKUP(G40,产品资料!C:C,产品资料!M:M)*J40,0) -> 33246 | P40: =IF(ISNUMBER(SEARCH("合包",R40)),SUMIFS(J:J,G:G,G:G,F:F,F:F)-SUMIFS(打包记录!J:J,打包记录!G:G,G:G,打包记录!F:F,F:F),SUMIFS(J:J,D:D,D:D,G:G,G:G,F:F,F:F)-SUMIFS(打包记录!J:J,打包记录!D:D,D:D,打包记录!G:G,G:G,打包记录!F:F,F:F)) -> 2 | Q40: 28
A41: 37 | B41: 46242 | C41: 乙白 | D41: 3000W-2 | E41: JGRWD002-00002047 | F41: 39407267 | G41: LP00032200 | H41: =_xlfn.XLOOKUP(G41,产品资料!C:C,产品资料!E:E) -> 4609左内垫板(0.8MM) | I41: =_xlfn.XLOOKUP(G41,产品资料!C:C,产品资料!F:F) -> 0.8*152*662 | J41: =20*Q41-K41 -> 314 | K41: 6 | L41: =_xlfn.XLOOKUP(G41,产品资料!C:C,产品资料!O:O)*J41 -> 193.44535 | M41: =IFERROR(_xlfn.XLOOKUP(G41,产品资料!C:C,产品资料!L:L)*J41,0) -> 557.664 | N41: =IFERROR(_xlfn.XLOOKUP(G41,产品资料!C:C,产品资料!M:M)*J41,0) -> 1884 | O41: 0.8*1250*11790*20张（97/191） | P41: =IF(ISNUMBER(SEARCH("合包",R41)),SUMIFS(J:J,G:G,G:G,F:F,F:F)-SUMIFS(打包记录!J:J,打包记录!G:G,G:G,打包记录!F:F,F:F),SUMIFS(J:J,D:D,D:D,G:G,G:G,F:F,F:F)-SUMIFS(打包记录!J:J,打包记录!D:D,D:D,打包记录!G:G,G:G,打包记录!F:F,F:F)) -> 4 | Q41: 16
A42: 38 | B42: 46242 | C42: 乙白 | D42: 3000W-2 | E42: JGRWD002-00002047 | F42: 39407267 | G42: LP00033300 | H42: =_xlfn.XLOOKUP(G42,产品资料!C:C,产品资料!E:E) -> 4609顶长拉手（0.8MM ） | I42: =_xlfn.XLOOKUP(G42,产品资料!C:C,产品资料!F:F) -> 0.8*168*1076 | J42: =20*Q42-K42 -> 155 | K42: 5 | L42: =_xlfn.XLOOKUP(G42,产品资料!C:C,产品资料!O:O)*J42 -> 175.37748 | M42: =IFERROR(_xlfn.XLOOKUP(G42,产品资料!C:C,产品资料!L:L)*J42,0) -> 384.71 | N42: =IFERROR(_xlfn.XLOOKUP(G42,产品资料!C:C,产品资料!M:M)*J42,0) -> 0 | P42: =IF(ISNUMBER(SEARCH("合包",R42)),SUMIFS(J:J,G:G,G:G,F:F,F:F)-SUMIFS(打包记录!J:J,打包记录!G:G,G:G,打包记录!F:F,F:F),SUMIFS(J:J,D:D,D:D,G:G,G:G,F:F,F:F)-SUMIFS(打包记录!J:J,打包记录!D:D,D:D,打包记录!G:G,G:G,打包记录!F:F,F:F)) -> 2 | Q42: 8
A43: 39 | B43: 46242 | C43: 乙白 | D43: 3000W-2 | E43: JGRWD002-00002047 | F43: 39407267 | G43: LP00033700 | H43: =_xlfn.XLOOKUP(G43,产品资料!C:C,产品资料!E:E) -> 4609中拉手(0.8MM） | I43: =_xlfn.XLOOKUP(G43,产品资料!C:C,产品资料!F:F) -> 0.8*155*515 | J43: =20*Q43-K43 -> 158 | K43: 2 | L43: =_xlfn.XLOOKUP(G43,产品资料!C:C,产品资料!O:O)*J43 -> 78.863235 | M43: =IFERROR(_xlfn.XLOOKUP(G43,产品资料!C:C,产品资料!L:L)*J43,0) -> 210.772 | N43: =IFERROR(_xlfn.XLOOKUP(G43,产品资料!C:C,产品资料!M:M)*J43,0) -> 0 | P43: =IF(ISNUMBER(SEARCH("合包",R43)),SUMIFS(J:J,G:G,G:G,F:F,F:F)-SUMIFS(打包记录!J:J,打包记录!G:G,G:G,打包记录!F:F,F:F),SUMIFS(J:J,D:D,D:D,G:G,G:G,F:F,F:F)-SUMIFS(打包记录!J:J,打包记录!D:D,D:D,打包记录!G:G,G:G,打包记录!F:F,F:F)) -> 10 | Q43: 8
...

Sheet 打包记录
A1: 序 | B1: 日期 | C1: 班 | D1: 机台 编号 | E1: 计划单号 | F1: 合同编号 | G1: 物料编码 | H1: 名称 | I1: 规格 | J1: 打包 数量 | K1: 净重 | L1: 毛重 | M1: 体积 长/宽/高 | N1: 柜号 | O1: 备注 | P1: 理算 净重/厚/木架重
A2: =ROW()-1 -> 1 | B2: 46189 | C2: 白 | D2: 3000W-2 | E2: JGRWD002-00001744 | F2: 39407267 | G2: LP00002600 | H2: =_xlfn.XLOOKUP(G2,产品资料!C:C,产品资料!E:E) -> 4609后排锁座(0.5) | I2: =_xlfn.XLOOKUP(G2,产品资料!C:C,产品资料!F:F) -> 0.5*110*755 | J2: 2475 | K2: 750 | L2: 765 | M2: 555*760*340 | N2: 13#-06 | O2: 截止到3000W-2-19 | P2: =ROUND(_xlfn.XLOOKUP(G2,产品资料!C:C,产品资料!O:O)*J2,0)&"/"&IFERROR(ROUND(K2/J2/(_xlfn.XLOOKUP(G2,产品资料!C:C,产品资料!N:N)*7.85),2),0)&"/"&L2-K2 -> 796/0.47/15
A3: =ROW()-1 -> 2 | B3: 46189 | C3: 白 | D3: 3000W-2 | E3: JGRWD002-00001744 | F3: 39407267 | G3: LP00002600 | H3: =_xlfn.XLOOKUP(G3,产品资料!C:C,产品资料!E:E) -> 4609后排锁座(0.5) | I3: =_xlfn.XLOOKUP(G3,产品资料!C:C,产品资料!F:F) -> 0.5*110*755 | J3: 3781 | K3: 1145 | L3: 1160 | M3: 555*760*425 | N3: 13#-07 | O3: 截止到3000W-2-48 | P3: =ROUND(_xlfn.XLOOKUP(G3,产品资料!C:C,产品资料!O:O)*J3,0)&"/"&IFERROR(ROUND(K3/J3/(_xlfn.XLOOKUP(G3,产品资料!C:C,产品资料!N:N)*7.85),2),0)&"/"&L3-K3 -> 1216/0.47/15
A4: =ROW()-1 -> 3 | B4: 46205 | C4: 夜 | D4: 3000W-1 | E4: JGRWD002-00001882 | F4: 39407267 | G4: LP00002400 | H4: =_xlfn.XLOOKUP(G4,产品资料!C:C,产品资料!E:E) -> 4609竖槽（0.8MM) | I4: =_xlfn.XLOOKUP(G4,产品资料!C:C,产品资料!F:F) -> 0.8*69*563 | J4: 2215 | K4: 492 | L4: 502 | M4: 580*430*390 | N4: 13#-10 | O4: 截止到3000W-1-638 | P4: =ROUND(_xlfn.XLOOKUP(G4,产品资料!C:C,产品资料!O:O)*J4,0)&"/"&IFERROR(ROUND(K4/J4/(_xlfn.XLOOKUP(G4,产品资料!C:C,产品资料!N:N)*7.85),2),0)&"/"&L4-K4 -> 515/0.76/10
A5: =ROW()-1 -> 4 | B5: 46206 | C5: 甲白 | D5: 3000W-1 | E5: JGRWD002-00001878 | F5: 39407267 | G5: LP00002400 | H5: =_xlfn.XLOOKUP(G5,产品资料!C:C,产品资料!E:E) -> 4609竖槽（0.8MM) | I5: =_xlfn.XLOOKUP(G5,产品资料!C:C,产品资料!F:F) -> 0.8*69*563 | J5: 1448 | K5: 324 | L5: 334 | M5: 580*430*315 | N5: 13#-11 | O5: 3663齐，截止到3000W-1-784 | P5: =ROUND(_xlfn.XLOOKUP(G5,产品资料!C:C,产品资料!O:O)*J5,0)&"/"&IFERROR(ROUND(K5/J5/(_xlfn.XLOOKUP(G5,产品资料!C:C,产品资料!N:N)*7.85),2),0)&"/"&L5-K5 -> 337/0.77/10
A6: =ROW()-1 -> 5 | B6: 46221 | C6: 白 | D6: 3000W-2 | E6: JGRWD002-00001964 | F6: 39407267 | G6: LP00003200 | H6: =_xlfn.XLOOKUP(G6,产品资料!C:C,产品资料!E:E) -> 4609平衡杆(镀锌0.9) | I6: =_xlfn.XLOOKUP(G6,产品资料!C:C,产品资料!F:F) -> 0.9*74*658 | J6: 1950 | K6: 644 | L6: 654 | M6: 670*460*400 | N6: 13#-12 | O6: 截止到3000W-2-24 | P6: =ROUND(_xlfn.XLOOKUP(G6,产品资料!C:C,产品资料!O:O)*J6,0)&"/"&IFERROR(ROUND(K6/J6/(_xlfn.XLOOKUP(G6,产品资料!C:C,产品资料!N:N)*7.85),2),0)&"/"&L6-K6 -> 660/0.88/10
A7: =ROW()-1 -> 6 | B7: 46221 | C7: 白 | D7: 3000W-2 | E7: JGRWD002-00001964 | F7: 39407267 | G7: LP00003200 | H7: =_xlfn.XLOOKUP(G7,产品资料!C:C,产品资料!E:E) -> 4609平衡杆(镀锌0.9) | I7: =_xlfn.XLOOKUP(G7,产品资料!C:C,产品资料!F:F) -> 0.9*74*658 | J7: 1713 | K7: 570 | L7: 580 | M7: 670*460*370 | N7: 13#-13 | O7: 3663齐 | P7: =ROUND(_xlfn.XLOOKUP(G7,产品资料!C:C,产品资料!O:O)*J7,0)&"/"&IFERROR(ROUND(K7/J7/(_xlfn.XLOOKUP(G7,产品资料!C:C,产品资料!N:N)*7.85),2),0)&"/"&L7-K7 -> 580/0.88/10
A8: =ROW()-1 -> 7 | B8: 46235 | C8: 乙夜 | D8: 3000W-1 | E8: JGRWD002-00001992 | F8: 39407267 | G8: LP00031700 | H8: =_xlfn.XLOOKUP(G8,产品资料!C:C,产品资料!E:E) -> 4609顶盖（0.8MM) | I8: =_xlfn.XLOOKUP(G8,产品资料!C:C,产品资料!F:F) -> 0.8*552*1168.5 | J8: 455 | K8: 1746 | L8: 1758 | M8: 565*1180*465 | N8: 10#-01 | O8: 截止到3000W-1-46 | P8: =ROUND(_xlfn.XLOOKUP(G8,产品资料!C:C,产品资料!O:O)*J8,0)&"/"&IFERROR(ROUND(K8/J8/(_xlfn.XLOOKUP(G8,产品资料!C:C,产品资料!N:N)*7.85),2),0)&"/"&L8-K8 -> 1839/0.76/12
A9: =ROW()-1 -> 8 | B9: 46235 | C9: 乙夜 | D9: 3000W-1 | E9: JGRWD002-00001992 | F9: 39407267 | G9: LP00031700 | H9: =_xlfn.XLOOKUP(G9,产品资料!C:C,产品资料!E:E) -> 4609顶盖（0.8MM) | I9: =_xlfn.XLOOKUP(G9,产品资料!C:C,产品资料!F:F) -> 0.8*552*1168.5 | J9: 460 | K9: 1764 | L9: 1776 | M9: 565*1180*465 | N9: 10#-02 | O9: 截止到3000W-1-92 | P9: =ROUND(_xlfn.XLOOKUP(G9,产品资料!C:C,产品资料!O:O)*J9,0)&"/"&IFERROR(ROUND(K9/J9/(_xlfn.XLOOKUP(G9,产品资料!C:C,产品资料!N:N)*7.85),2),0)&"/"&L9-K9 -> 1859/0.76/12
A10: =ROW()-1 -> 9 | B10: 46237 | C10: 乙白 | D10: 3000W-2 | E10: JGRWD002-00001992 | F10: 39407267 | G10: LP00031900 | H10: =_xlfn.XLOOKUP(G10,产品资料!C:C,产品资料!E:E) -> 4609左侧板(0.8MM) | I10: =_xlfn.XLOOKUP(G10,产品资料!C:C,产品资料!F:F) -> 0.8*534.5*789 | J10: 521 | K10: 1298 | L10: 1308 | M10: 550*800*510 | N10: 10#-03 | O10: 截止到3000W-2-19 | P10: =ROUND(_xlfn.XLOOKUP(G10,产品资料!C:C,产品资料!O:O)*J10,0)&"/"&IFERROR(ROUND(K10/J10/(_xlfn.XLOOKUP(G10,产品资料!C:C,产品资料!N:N)*7.85),2),0)&"/"&L10-K10 -> 1364/0.76/10
A11: =ROW()-1 -> 10 | B11: 46237 | C11: 乙白 | D11: 3000W-2 | E11: JGRWD002-00001992 | F11: 39407267 | G11: LP00031900 | H11: =_xlfn.XLOOKUP(G11,产品资料!C:C,产品资料!E:E) -> 4609左侧板(0.8MM) | I11: =_xlfn.XLOOKUP(G11,产品资料!C:C,产品资料!F:F) -> 0.8*534.5*789 | J11: 532 | K11: 1326 | L11: 1336 | M11: 550*800*520 | N11: 10#-04 | O11: 截止到3000W-2-38 | P11: =ROUND(_xlfn.XLOOKUP(G11,产品资料!C:C,产品资料!O:O)*J11,0)&"/"&IFERROR(ROUND(K11/J11/(_xlfn.XLOOKUP(G11,产品资料!C:C,产品资料!N:N)*7.85),2),0)&"/"&L11-K11 -> 1393/0.76/10
A12: =ROW()-1 -> 11 | B12: 46237 | C12: 乙白 | D12: 3000W-2 | E12: JGRWD002-00001992 | F12: 39407267 | G12: LP00031900 | H12: =_xlfn.XLOOKUP(G12,产品资料!C:C,产品资料!E:E) -> 4609左侧板(0.8MM) | I12: =_xlfn.XLOOKUP(G12,产品资料!C:C,产品资料!F:F) -> 0.8*534.5*789 | J12: 532 | K12: 1324 | L12: 1334 | M12: 550*800*520 | N12: 10#-05 | O12: 截止到3000W-2-57 | P12: =ROUND(_xlfn.XLOOKUP(G12,产品资料!C:C,产品资料!O:O)*J12,0)&"/"&IFERROR(ROUND(K12/J12/(_xlfn.XLOOKUP(G12,产品资料!C:C,产品资料!N:N)*7.85),2),0)&"/"&L12-K12 -> 1393/0.76/10
A13: =ROW()-1 -> 12 | B13: 46238 | C13: 乙白 | D13: 3000W-2 | E13: JGRWD002-00001992 | F13: 39407267 | G13: LP00031900 | H13: =_xlfn.XLOOKUP(G13,产品资料!C:C,产品资料!E:E) -> 4609左侧板(0.8MM) | I13: =_xlfn.XLOOKUP(G13,产品资料!C:C,产品资料!F:F) -> 0.8*534.5*789 | J13: 532 | K13: 1324 | L13: 1334 | M13: 550*800*520 | N13: 10#-06 | O13: 截止到3000W-2-76 | P13: =ROUND(_xlfn.XLOOKUP(G13,产品资料!C:C,产品资料!O:O)*J13,0)&"/"&IFERROR(ROUND(K13/J13/(_xlfn.XLOOKUP(G13,产品资料!C:C,产品资料!N:N)*7.85),2),0)&"/"&L13-K13 -> 1393/0.76/10
... A24: =ROW()-1 -> 23 | B24: 46239 | C24: 乙白 | D24: 3000W-2 | E24: JGRWD002-00002047 | F24: 39407267 | G24: LP00031900 | H24: =_xlfn.XLOOKUP(G24,产品资料!C:C,产品资料!E:E) -> 4609左侧板(0.8MM) | I24: =_xlfn.XLOOKUP(G24,产品资料!C:C,产品资料!F:F) -> 0.8*534.5*789 | J24: 451 | K24: 1130 | L24: 1140 | M24: 550*800*455 | N24: 10#-17 | O24: 7326齐 | P24: =ROUND(_xlfn.XLOOKUP(G24,产品资料!C:C,产品资料!O:O)*J24,0)&"/"&IFERROR(ROUND(K24/J24/(_xlfn.XLOOKUP(G24,产品资料!C:C,产品资料!N:N)*7.85),2),0)&"/"&L24-K24 -> 1181/0.77/10
A25: =ROW()-1 -> 24 | B25: 46239 | C25: 乙白 | D25: 3000W-2 | E25: JGRWD002-00002047 | F25: 39407267 | G25: LP00033900 | H25: =_xlfn.XLOOKUP(G25,产品资料!C:C,产品资料!E:E) -> 4609大拉手(0.8MM） | I25: =_xlfn.XLOOKUP(G25,产品资料!C:C,产品资料!F:F) -> 0.8*303*515 | J25: 1045 | K25: 970 | L25: 980 | M25: 620*530*510 | N25: 10#-18 | P25: =ROUND(_xlfn.XLOOKUP(G25,产品资料!C:C,产品资料!O:O)*J25,0)&"/"&IFERROR(ROUND(K25/J25/(_xlfn.XLOOKUP(G25,产品资料!C:C,产品资料!N:N)*7.85),2),0)&"/"&L25-K25 -> 1022/0.76/10
A26: =ROW()-1 -> 25 | B26: 46240 | C26: 甲夜 | D26: 3000W-1 | E26: JGRWD002-00002047 | F26: 39407267 | G26: LP00031700 | H26: =_xlfn.XLOOKUP(G26,产品资料!C:C,产品资料!E:E) -> 4609顶盖（0.8MM) | I26: =_xlfn.XLOOKUP(G26,产品资料!C:C,产品资料!F:F) -> 0.8*552*1168.5 | J26: 458 | K26: 1758 | L26: 1770 | M26: 565*1180*465 | N26: 11#-01 | O26: 截止到3000W-1-38 | P26: =ROUND(_xlfn.XLOOKUP(G26,产品资料!C:C,产品资料!O:O)*J26,0)&"/"&IFERROR(ROUND(K26/J26/(_xlfn.XLOOKUP(G26,产品资料!C:C,产品资料!N:N)*7.85),2),0)&"/"&L26-K26 -> 1851/0.76/12
A27: =ROW()-1 -> 26 | B27: 46240 | C27: 甲白 | D27: 3000W-2 | E27: JGRWD002-00002047 | F27: 39407267 | G27: LP00033800 | H27: =_xlfn.XLOOKUP(G27,产品资料!C:C,产品资料!E:E) -> 4609大抽斗(0.8MM) | I27: =_xlfn.XLOOKUP(G27,产品资料!C:C,产品资料!F:F) -> 0.8*418*919 | J27: 525 | K27: 1198 | L27: 1208 | M27: 430*930*515 | N27: 11#-02 | O27: 截止到3000W-2-19 | P27: =ROUND(_xlfn.XLOOKUP(G27,产品资料!C:C,产品资料!O:O)*J27,0)&"/"&IFERROR(ROUND(K27/J27/(_xlfn.XLOOKUP(G27,产品资料!C:C,产品资料!N:N)*7.85),2),0)&"/"&L27-K27 -> 1261/0.76/10
A28: =ROW()-1 -> 27 | B28: 46240 | C28: 甲白 | D28: 3000W-2 | E28: JGRWD002-00002047 | F28: 39407267 | G28: LP00033800 | H28: =_xlfn.XLOOKUP(G28,产品资料!C:C,产品资料!E:E) -> 4609大抽斗(0.8MM) | I28: =_xlfn.XLOOKUP(G28,产品资料!C:C,产品资料!F:F) -> 0.8*418*919 | J28: 532 | K28: 1212 | L28: 1222 | M28: 430*930*520 | N28: 11#-03 | O28: 截止到3000W-2-38 | P28: =ROUND(_xlfn.XLOOKUP(G28,产品资料!C:C,产品资料!O:O)*J28,0)&"/"&IFERROR(ROUND(K28/J28/(_xlfn.XLOOKUP(G28,产品资料!C:C,产品资料!N:N)*7.85),2),0)&"/"&L28-K28 -> 1278/0.76/10
A29: =ROW()-1 -> 28 | B29: 46240 | C29: 甲白 | D29: 3000W-2 | E29: JGRWD002-00002047 | F29: 39407267 | G29: LP00033300 | H29: =_xlfn.XLOOKUP(G29,产品资料!C:C,产品资料!E:E) -> 4609顶长拉手（0.8MM ） | I29: =_xlfn.XLOOKUP(G29,产品资料!C:C,产品资料!F:F) -> 0.8*168*1076 | J29: 1226 | K29: 1302 | L29: 1316 | M29: 520*1090*430 | N29: 11#-04 | O29: 截止到3000W-2-46 | P29: =ROUND(_xlfn.XLOOKUP(G29,产品资料!C:C,产品资料!O:O)*J29,0)&"/"&IFERROR(ROUND(K29/J29/(_xlfn.XLOOKUP(G29,产品资料!C:C,产品资料!N:N)*7.85),2),0)&"/"&L29-K29 -> 1387/0.75/14
A30: =ROW()-1 -> 29 | B30: 46240 | C30: 甲白 | D30: 3000W-2 | E30: JGRWD002-00002047 | F30: 39407267 | G30: LP00033800 | H30: =_xlfn.XLOOKUP(G30,产品资料!C:C,产品资料!E:E) -> 4609大抽斗(0.8MM) | I30: =_xlfn.XLOOKUP(G30,产品资料!C:C,产品资料!F:F) -> 0.8*418*919 | J30: 531 | K30: 1210 | L30: 1220 | M30: 430*930*520 | N30: 11#-05 | O30: 截止到3000W-2-57 | P30: =ROUND(_xlfn.XLOOKUP(G30,产品资料!C:C,产品资料!O:O)*J30,0)&"/"&IFERROR(ROUND(K30/J30/(_xlfn.XLOOKUP(G30,产品资料!C:C,产品资料!N:N)*7.85),2),0)&"/"&L30-K30 -> 1275/0.76/10
A31: =ROW()-1 -> 30 | B31: 46240 | C31: 甲白 | D31: 3000W-2 | E31: JGRWD002-00002047 | F31: 39407267 | G31: LP00033800 | H31: =_xlfn.XLOOKUP(G31,产品资料!C:C,产品资料!E:E) -> 4609大抽斗(0.8MM) | I31: =_xlfn.XLOOKUP(G31,产品资料!C:C,产品资料!F:F) -> 0.8*418*919 | J31: 532 | K31: 1212 | L31: 1222 | M31: 430*930*520 | N31: 11#-06 | O31: 截止到3000W-2-76 | P31: =ROUND(_xlfn.XLOOKUP(G31,产品资料!C:C,产品资料!O:O)*J31,0)&"/"&IFERROR(ROUND(K31/J31/(_xlfn.XLOOKUP(G31,产品资料!C:C,产品资料!N:N)*7.85),2),0)&"/"&L31-K31 -> 1278/0.76/10
A32: =ROW()-1 -> 31 | B32: 46242 | C32: 乙白 | D32: 3000W-2 | E32: JGRWD002-00002047 | F32: 39407267 | G32: LP00032200 | H32: =_xlfn.XLOOKUP(G32,产品资料!C:C,产品资料!E:E) -> 4609左内垫板(0.8MM) | I32: =_xlfn.XLOOKUP(G32,产品资料!C:C,产品资料!F:F) -> 0.8*152*662 | J32: 1511 | K32: 876 | L32: 886 | M32: 675*470*510 | N32: 11#-07 | O32: 截止到3000W-2-95 | P32: =ROUND(_xlfn.XLOOKUP(G32,产品资料!C:C,产品资料!O:O)*J32,0)&"/"&IFERROR(ROUND(K32/J32/(_xlfn.XLOOKUP(G32,产品资料!C:C,产品资料!N:N)*7.85),2),0)&"/"&L32-K32 -> 931/0.75/10
A33: =ROW()-1 -> 32 | B33: 46242 | C33: 乙白 | D33: 3000W-2 | E33: JGRWD002-00002047 | F33: 39407267 | G33: LP00033800 | H33: =_xlfn.XLOOKUP(G33,产品资料!C:C,产品资料!E:E) -> 4609大抽斗(0.8MM) | I33: =_xlfn.XLOOKUP(G33,产品资料!C:C,产品资料!F:F) -> 0.8*418*919 | J33: 531 | K33: 1210 | L33: 1220 | M33: 430*930*520 | N33: 11#-08 | O33: 截止到3000W-2-95 | P33: =ROUND(_xlfn.XLOOKUP(G33,产品资料!C:C,产品资料!O:O)*J33,0)&"/"&IFERROR(ROUND(K33/J33/(_xlfn.XLOOKUP(G33,产品资料!C:C,产品资料!N:N)*7.85),2),0)&"/"&L33-K33 -> 1275/0.76/10
A34: =ROW()-1 -> 33 | B34: 46242 | C34: 乙白 | D34: 3000W-2 | E34: JGRWD002-00002087 | F34: 39407267 | G34: LP00033100 | H34: =_xlfn.XLOOKUP(G34,产品资料!C:C,产品资料!E:E) -> 4609横槽(0.9MM) | I34: =_xlfn.XLOOKUP(G34,产品资料!C:C,产品资料!F:F) -> 0.9*86.5*1168.5 | J34: 1813 | K34: 1241 | L34: 1266 | M34: 530*1180*375 | N34: 11#-09 | O34: 截止到3000W-2-53 | P34: =ROUND(_xlfn.XLOOKUP(G34,产品资料!C:C,产品资料!O:O)*J34,0)&"/"&IFERROR(ROUND(K34/J34/(_xlfn.XLOOKUP(G34,产品资料!C:C,产品资料!N:N)*7.85),2),0)&"/"&L34-K34 -> 1286/0.87/25
A35: =ROW()-1 -> 34 | B35: 46244 | C35: 乙白 | D35: 3000W-2 | E35: JGRWD002-00002047 | F35: 39407267 | G35: LP00033800 | H35: =_xlfn.XLOOKUP(G35,产品资料!C:C,产品资料!E:E) -> 4609大抽斗(0.8MM) | I35: =_xlfn.XLOOKUP(G35,产品资料!C:C,产品资料!F:F) -> 0.8*418*919 | J35: 518 | K35: 1180 | L35: 1190 | M35: 430*930*510 | N35: 11#-10 | O35: 截止到3000W-2-114 | P35: =ROUND(_xlfn.XLOOKUP(G35,产品资料!C:C,产品资料!O:O)*J35,0)&"/"&IFERROR(ROUND(K35/J35/(_xlfn.XLOOKUP(G35,产品资料!C:C,产品资料!N:N)*7.85),2),0)&"/"&L35-K35 -> 1244/0.76/10
A36: =ROW()-1 -> 35 | B36: 46244 | C36: 乙白 | D36: 3000W-2 | E36: JGRWD002-00002047 | F36: 39407267 | G36: LP00033800 | H36: =_xlfn.XLOOKUP(G36,产品资料!C:C,产品资料!E:E) -> 4609大抽斗(0.8MM) | I36: =_xlfn.XLOOKUP(G36,产品资料!C:C,产品资料!F:F) -> 0.8*418*919 | J36: 532 | K36: 1206 | L36: 1216 | M36: 430*930*515 | N36: 11#-11 | O36: 截止到3000W-2-133 | P36: =ROUND(_xlfn.XLOOKUP(G36,产品资料!C:C,产品资料!O:O)*J36,0)&"/"&IFERROR(ROUND(K36/J36/(_xlfn.XLOOKUP(G36,产品资料!C:C,产品资料!N:N)*7.85),2),0)&"/"&L36-K36 -> 1278/0.76/10
A37: =ROW()-1 -> 36 | B37: 46244 | C37: 乙白 | D37: 3000W-2 | E37: JGRWD002-00002047 | F37: 39407267 | G37: LP00033800 | H37: =_xlfn.XLOOKUP(G37,产品资料!C:C,产品资料!E:E) -> 4609大抽斗(0.8MM) | I37: =_xlfn.XLOOKUP(G37,产品资料!C:C,产品资料!F:F) -> 0.8*418*919 | J37: 532 | K37: 1210 | L37: 1220 | M37: 430*930*515 | N37: 11#-12 | O37: 截止到3000W-2-152 | P37: =ROUND(_xlfn.XLOOKUP(G37,产品资料!C:C,产品资料!O:O)*J37,0)&"/"&IFERROR(ROUND(K37/J37/(_xlfn.XLOOKUP(G37,产品资料!C:C,产品资料!N:N)*7.85),2),0)&"/"&L37-K37 -> 1278/0.76/10
... A138: =ROW()-1 -> 137 | B138: 46276 | C138: 甲白 | D138: 3000W-2 | E138: JGRWD002-00002193 | F138: 39407267 | G138: LP00033400 | H138: =_xlfn.XLOOKUP(G138,产品资料!C:C,产品资料!E:E) -> 4609小抽斗(0.8MM) | I138: =_xlfn.XLOOKUP(G138,产品资料!C:C,产品资料!F:F) -> 0.8*418*603 | J138: 983 | K138: 1462 | L138: 1472 | M138: 615*850*480 | N138: 17#-04 | O138: 截止到3000W-2-8 | P138: =ROUND(_xlfn.XLOOKUP(G138,产品资料!C:C,产品资料!O:O)*J138,0)&"/"&IFERROR(ROUND(K138/J138/(_xlfn.XLOOKUP(G138,产品资料!C:C,产品资料!N:N)*7.85),2),0)&"/"&L138-K138 -> 1546/0.76/10
A139: =ROW()-1 -> 138 | B139: 46276 | C139: 甲白 | D139: 3000W-2 | E139: JGRWD002-00002253 | F139: 39407267 | G139: LP00033400 | H139: =_xlfn.XLOOKUP(G139,产品资料!C:C,产品资料!E:E) -> 4609小抽斗(0.8MM) | I139: =_xlfn.XLOOKUP(G139,产品资料!C:C,产品资料!F:F) -> 0.8*418*603 | J139: 909 | K139: 1358 | L139: 1368 | M139: 615*850*480 | N139: 17#-11 | O139: 14652齐 | P139: =ROUND(_xlfn.XLOOKUP(G139,产品资料!C:C,产品资料!O:O)*J139,0)&"/"&IFERROR(ROUND(K139/J139/(_xlfn.XLOOKUP(G139,产品资料!C:C,产品资料!N:N)*7.85),2),0)&"/"&L139-K139 -> 1430/0.76/10 | Q139: 1
A140: =ROW()-1 -> 139 | B140: 46277 | C140: 甲白 | D140: 3000W-2 | E140: JGRWD002-00002253 | F140: 39407267 | G140: LP00033200 | H140: =_xlfn.XLOOKUP(G140,产品资料!C:C,产品资料!E:E) -> 4609顶长抽斗(0.8MM) | I140: =_xlfn.XLOOKUP(G140,产品资料!C:C,产品资料!F:F) -> 0.8*418*1210 | J140: 496 | K140: 1488 | L140: 1498 | M140: 430*1225*480 | N140: 17#-12 | O140: 截止到3000W-2-13 | P140: =ROUND(_xlfn.XLOOKUP(G140,产品资料!C:C,产品资料!O:O)*J140,0)&"/"&IFERROR(ROUND(K140/J140/(_xlfn.XLOOKUP(G140,产品资料!C:C,产品资料!N:N)*7.85),2),0)&"/"&L140-K140 -> 1570/0.76/10 | Q140: 1
A141: =ROW()-1 -> 140 | B141: 46277 | C141: 甲白 | D141: 3000W-2 | E141: JGRWD002-00002253 | F141: 39407267 | G141: LP00033200 | H141: =_xlfn.XLOOKUP(G141,产品资料!C:C,产品资料!E:E) -> 4609顶长抽斗(0.8MM) | I141: =_xlfn.XLOOKUP(G141,产品资料!C:C,产品资料!F:F) -> 0.8*418*1210 | J141: 535 | K141: 1608 | L141: 1618 | M141: 430*1225*525 | N141: 17#-13 | O141: 截止到3000W-2-25 | P141: =ROUND(_xlfn.XLOOKUP(G141,产品资料!C:C,产品资料!O:O)*J141,0)&"/"&IFERROR(ROUND(K141/J141/(_xlfn.XLOOKUP(G141,产品资料!C:C,产品资料!N:N)*7.85),2),0)&"/"&L141-K141 -> 1693/0.76/10 | Q141: 1
A142: =ROW()-1 -> 141 | B142: 46277 | C142: 甲白 | D142: 3000W-2 | E142: JGRWD002-00002253 | F142: 39407267 | G142: LP00033200 | H142: =_xlfn.XLOOKUP(G142,产品资料!C:C,产品资料!E:E) -> 4609顶长抽斗(0.8MM) | I142: =_xlfn.XLOOKUP(G142,产品资料!C:C,产品资料!F:F) -> 0.8*418*1210 | J142: 538 | K142: 1620 | L142: 1630 | M142: 430*1225*530 | N142: 17#-14 | O142: 3663齐 | P142: =ROUND(_xlfn.XLOOKUP(G142,产品资料!C:C,产品资料!O:O)*J142,0)&"/"&IFERROR(ROUND(K142/J142/(_xlfn.XLOOKUP(G142,产品资料!C:C,产品资料!N:N)*7.85),2),0)&"/"&L142-K142 -> 1703/0.76/10 | Q142: 1

Sheet 标签
A1: Factory name | B1: juquan | C1: Material Number | D1: {=LOOKUP(1,0/(打包记录!I:I=标签!D2),打包记录!G:G)} -> LP00033200
A2: Net Weight (kg) | B2: {=LOOKUP(1,0/(打包记录!I:I=标签!D2),打包记录!K:K)} -> 1620 | C2: Material Specification | D2: 0.8*418*1210
A3: Gross Weight (kg) | B3: {=LOOKUP(1,0/(打包记录!I:I=标签!D2),打包记录!L:L)} -> 1630 | C3: Material Quantity | D3: {=LOOKUP(1,0/(打包记录!I:I=标签!D2),打包记录!J:J)} -> 538
A4: =_xlfn.XLOOKUP(B5,订单数量!C:C,订单数量!B:B,"") -> CPI-260609-5 | C4: Material | D4: SPCC
A5: contract number | B5: {=LOOKUP(1,0/(打包记录!I:I=标签!D2),打包记录!F:F)} -> 39407267 | C5: Date In Producted | D5: {=LOOKUP(1,0/(打包记录!I:I=标签!D2),打包记录!B:B)} -> 46277
A6: bar code | C6: QC | D6: Liu Baishui
A7: {=LOOKUP(1,0/(标签!$D$1=打包记录!$G:$G),打包记录!$N:$N)} -> 17#-14

Sheet 标签 (2)
A1: 客户名称 | B1: 脉翔
A2: 材质
A3: 规格 | B3: 0.8*990*1400
A4: 净重KG | C4: 数量 | D4: 358
A5: 毛重KG | C5: 日期
